[2021-10-18 16:31:55,492][INFO][4513287680][main.py:88]SSRSpeed 1.01, Web Api Version 0.5.2
[2021-10-18 16:31:55,493][INFO][4513287680][platform_check.py:9]Platform Info : macOS-11.6-x86_64-i386-64bit
[2021-10-18 16:31:55,493][INFO][4513287680][requirements_check.py:73]Checking libsodium.
[2021-10-18 16:31:55,493][INFO][4513287680][platform_check.py:9]Platform Info : macOS-11.6-x86_64-i386-64bit
[2021-10-18 16:31:59,072][INFO][4513287680][requirements_check.py:57]Checking ./clients/v2ray-core/v2ctl
[2021-10-18 16:31:59,073][INFO][4513287680][requirements_check.py:57]Checking ./clients/v2ray-core/v2ray
[2021-10-18 16:31:59,074][INFO][4513287680][requirements_check.py:123]Shadowsocks-libev found /usr/local/bin/ss-local
[2021-10-18 16:31:59,074][INFO][4513287680][requirements_check.py:120]Obfs-Local found /usr/local/bin/obfs-local
[2021-10-18 16:31:59,075][INFO][4513287680][config_parser.py:176]Reading https://fast.losadhwselfff2332dasd.xyz/link/UHFeqi6SwVAesyOi?clash=2
[2021-10-18 16:32:01,182][INFO][4513287680][config_parser.py:220]Base64 decode failed.
[2021-10-18 16:32:01,721][WARNING][4513287680][node_filters.py:37]香港 - 1 官网: https://管人痴.com (127.0.0.1:33400) already in list.
[2021-10-18 16:32:01,767][WARNING][4513287680][node_filters.py:37]香港 - 中国-日本 多协议标签交换虚拟专用网（三） H 1000Mbps (hr07.cathayroute.com:33400) already in list.
[2021-10-18 16:32:01,956][WARNING][4513287680][node_filters.py:37]香港 - 本站无Ins推广渠道 Ins推广渠道均为二手倒卖 (127.0.0.1:33400) already in list.
[2021-10-18 16:32:01,956][WARNING][4513287680][node_filters.py:37]香港 - 本站无QQ购买渠道 QQ卖家购买均为二手倒卖 (127.0.0.1:33400) already in list.
[2021-10-18 16:32:01,956][WARNING][4513287680][node_filters.py:37]香港 - 本站无微信购买渠道 微信购买均为二手倒卖 (127.0.0.1:33400) already in list.
[2021-10-18 16:32:02,018][WARNING][4513287680][node_filters.py:37]香港 - 精简 30 (30.secureencryptedvirtualization.com:33400) already in list.
[2021-10-18 16:32:03,147][INFO][4513287680][config_parser.py:152]香港 - 1 加入用户群: https://t.me/joinchat/j_AxEbSzcX85NWI1
[2021-10-18 16:32:03,147][INFO][4513287680][config_parser.py:152]香港 - ASYNCHRONOUS TRANSFERMODE 永久虚通路连接PVCC C01
[2021-10-18 16:32:03,148][INFO][4513287680][config_parser.py:152]香港 - IPV6 俄罗斯 C01
[2021-10-18 16:32:03,148][INFO][4513287680][config_parser.py:152]香港 - IPV6 加拿大 C01
[2021-10-18 16:32:03,148][INFO][4513287680][config_parser.py:152]香港 - IPV6 日本 C01
[2021-10-18 16:32:03,149][INFO][4513287680][config_parser.py:152]香港 - IPV6 法国 C01
[2021-10-18 16:32:03,149][INFO][4513287680][config_parser.py:152]香港 - IPV6 澳大利亚 C01
[2021-10-18 16:32:03,149][INFO][4513287680][config_parser.py:152]香港 - 中国-加拿大 IPLC C01
[2021-10-18 16:32:03,150][INFO][4513287680][config_parser.py:152]香港 - 中国-加拿大 IPLC C02
[2021-10-18 16:32:03,150][INFO][4513287680][config_parser.py:152]香港 - 中国-加拿大 IPLC C03
[2021-10-18 16:32:03,152][INFO][4513287680][config_parser.py:152]香港 - 中国-加拿大 IPLC C04
[2021-10-18 16:32:03,152][INFO][4513287680][config_parser.py:152]香港 - 中国-加拿大 IPLC C05
[2021-10-18 16:32:03,153][INFO][4513287680][config_parser.py:152]香港 - 中国-印度 班加罗尔 एयरटेल IPLC C01
[2021-10-18 16:32:03,154][INFO][4513287680][config_parser.py:152]香港 - 中国-印度 班加罗尔 एयरटेल IPLC C02
[2021-10-18 16:32:03,154][INFO][4513287680][config_parser.py:152]香港 - 中国-印度 班加罗尔 एयरटेल IPLC C03
[2021-10-18 16:32:03,155][INFO][4513287680][config_parser.py:152]香港 - 中国-印度 班加罗尔 एयरटेल IPLC C04
[2021-10-18 16:32:03,156][INFO][4513287680][config_parser.py:152]香港 - 中国-印度 班加罗尔 एयरटेल IPLC C05
[2021-10-18 16:32:03,156][INFO][4513287680][config_parser.py:152]香港 - 中国-印度 班加罗尔 एयरटेल IPLC C06
[2021-10-18 16:32:03,157][INFO][4513287680][config_parser.py:152]香港 - 中国-印度 班加罗尔 एयरटेल IPLC C07
[2021-10-18 16:32:03,157][INFO][4513287680][config_parser.py:152]香港 - 中国-印度 班加罗尔 एयरटेल IPLC C08
[2021-10-18 16:32:03,157][INFO][4513287680][config_parser.py:152]香港 - 中国-印度 班加罗尔 एयरटेल IPLC C09
[2021-10-18 16:32:03,158][INFO][4513287680][config_parser.py:152]香港 - 中国-台湾 VPDN 嘉义游戏专线 C01 Netflix 动画疯
[2021-10-18 16:32:03,158][INFO][4513287680][config_parser.py:152]香港 - 中国-台湾 VPDN 嘉义游戏专线 C02 Netflix 动画疯
[2021-10-18 16:32:03,158][INFO][4513287680][config_parser.py:152]香港 - 中国-台湾 VPDN 嘉义游戏专线 C03 Netflix 动画疯
[2021-10-18 16:32:03,158][INFO][4513287680][config_parser.py:152]香港 - 中国-台湾 VPDN 嘉义游戏专线 C04 Netflix 动画疯
[2021-10-18 16:32:03,159][INFO][4513287680][config_parser.py:152]香港 - 中国-台湾 VPDN 嘉义游戏专线 C05 Netflix 动画疯
[2021-10-18 16:32:03,159][INFO][4513287680][config_parser.py:152]香港 - 中国-台湾 VPDN 嘉义游戏专线 C06 Netflix 动画疯
[2021-10-18 16:32:03,159][INFO][4513287680][config_parser.py:152]香港 - 中国-台湾 VPDN 嘉义游戏专线 C07 Netflix 动画疯
[2021-10-18 16:32:03,160][INFO][4513287680][config_parser.py:152]香港 - 中国-台湾 VPDN 嘉义游戏专线 C08 Netflix 动画疯
[2021-10-18 16:32:03,160][INFO][4513287680][config_parser.py:152]香港 - 中国-台湾 VPDN 嘉义游戏专线 C09 Netflix 动画疯
[2021-10-18 16:32:03,162][INFO][4513287680][config_parser.py:152]香港 - 中国-台湾 VPDN 嘉义游戏专线 C10 Netflix 动画疯
[2021-10-18 16:32:03,163][INFO][4513287680][config_parser.py:152]香港 - 中国-台湾彰化 IEPL HiNet固接 C01 Netflix 动画疯
[2021-10-18 16:32:03,164][INFO][4513287680][config_parser.py:152]香港 - 中国-台湾彰化 IEPL HiNet固接 C02 Netflix 动画疯
[2021-10-18 16:32:03,164][INFO][4513287680][config_parser.py:152]香港 - 中国-台湾彰化 IEPL HiNet固接 C03 Netflix 动画疯
[2021-10-18 16:32:03,165][INFO][4513287680][config_parser.py:152]香港 - 中国-台湾彰化 IEPL HiNet固接 C04 Netflix 动画疯
[2021-10-18 16:32:03,166][INFO][4513287680][config_parser.py:152]香港 - 中国-台湾彰化 IEPL HiNet固接 C05 Netflix 动画疯
[2021-10-18 16:32:03,166][INFO][4513287680][config_parser.py:152]香港 - 中国-台湾彰化 IEPL HiNet固接 C06 Netflix 动画疯
[2021-10-18 16:32:03,167][INFO][4513287680][config_parser.py:152]香港 - 中国-台湾彰化 IEPL HiNet固接 C07 Netflix 动画疯
[2021-10-18 16:32:03,168][INFO][4513287680][config_parser.py:152]香港 - 中国-台湾彰化 IEPL HiNet固接 C08 Netflix 动画疯
[2021-10-18 16:32:03,168][INFO][4513287680][config_parser.py:152]香港 - 中国-台湾彰化 IEPL HiNet固接 C09 Netflix 动画疯
[2021-10-18 16:32:03,169][INFO][4513287680][config_parser.py:152]香港 - 中国-台湾彰化 IEPL HiNet固接 C10 Netflix 动画疯
[2021-10-18 16:32:03,170][INFO][4513287680][config_parser.py:152]香港 - 中国-台湾桃园 IPLC 台湾固网 C01 Netflix 动画疯
[2021-10-18 16:32:03,171][INFO][4513287680][config_parser.py:152]香港 - 中国-台湾桃园 IPLC 台湾固网 C02 Netflix 动画疯
[2021-10-18 16:32:03,171][INFO][4513287680][config_parser.py:152]香港 - 中国-台湾桃园 IPLC 台湾固网 C03 Netflix 动画疯
[2021-10-18 16:32:03,172][INFO][4513287680][config_parser.py:152]香港 - 中国-台湾桃园 IPLC 台湾固网 C04 Netflix 动画疯
[2021-10-18 16:32:03,172][INFO][4513287680][config_parser.py:152]香港 - 中国-台湾桃园 IPLC 台湾固网 C05 Netflix 动画疯
[2021-10-18 16:32:03,173][INFO][4513287680][config_parser.py:152]香港 - 中国-台湾桃园 IPLC 台湾固网 C06 Netflix 动画疯
[2021-10-18 16:32:03,173][INFO][4513287680][config_parser.py:152]香港 - 中国-台湾桃园 IPLC 台湾固网 C07 Netflix 动画疯
[2021-10-18 16:32:03,174][INFO][4513287680][config_parser.py:152]香港 - 中国-台湾桃园 IPLC 台湾固网 C08 Netflix 动画疯
[2021-10-18 16:32:03,174][INFO][4513287680][config_parser.py:152]香港 - 中国-台湾桃园 IPLC 台湾固网 C09 Netflix 动画疯
[2021-10-18 16:32:03,175][INFO][4513287680][config_parser.py:152]香港 - 中国-台湾桃园 IPLC 台湾固网 C10 Netflix 动画疯
[2021-10-18 16:32:03,175][INFO][4513287680][config_parser.py:152]香港 - 中国-台湾桃园 IPLC 台湾固网 C11 Netflix 动画疯
[2021-10-18 16:32:03,175][INFO][4513287680][config_parser.py:152]香港 - 中国-日本 多协议标签交换虚拟专用网（三） A 1000Mbps
[2021-10-18 16:32:03,177][INFO][4513287680][config_parser.py:152]香港 - 中国-日本 多协议标签交换虚拟专用网（三） B 1000Mbps
[2021-10-18 16:32:03,178][INFO][4513287680][config_parser.py:152]香港 - 中国-日本 多协议标签交换虚拟专用网（三） C 1000Mbps
[2021-10-18 16:32:03,180][INFO][4513287680][config_parser.py:152]香港 - 中国-日本 多协议标签交换虚拟专用网（三） D 1000Mbps
[2021-10-18 16:32:03,181][INFO][4513287680][config_parser.py:152]香港 - 中国-日本 多协议标签交换虚拟专用网（三） E 1000Mbps
[2021-10-18 16:32:03,183][INFO][4513287680][config_parser.py:152]香港 - 中国-日本 多协议标签交换虚拟专用网（三） F 1000Mbps
[2021-10-18 16:32:03,184][INFO][4513287680][config_parser.py:152]香港 - 中国-日本 多协议标签交换虚拟专用网（三） G 1000Mbps
[2021-10-18 16:32:03,185][INFO][4513287680][config_parser.py:152]香港 - 中国-日本 多协议标签交换虚拟专用网（三） I 1000Mbps
[2021-10-18 16:32:03,186][INFO][4513287680][config_parser.py:152]香港 - 中国-日本 多协议标签交换虚拟专用网（三） J 1000Mbps
[2021-10-18 16:32:03,187][INFO][4513287680][config_parser.py:152]香港 - 中国-日本 沪日IEPL传输 Equinix-TY8 C01 Netflix
[2021-10-18 16:32:03,189][INFO][4513287680][config_parser.py:152]香港 - 中国-日本 沪日IEPL传输 Equinix-TY8 C02 Netflix
[2021-10-18 16:32:03,189][INFO][4513287680][config_parser.py:152]香港 - 中国-日本 沪日IEPL传输 Equinix-TY8 C03 Netflix
[2021-10-18 16:32:03,190][INFO][4513287680][config_parser.py:152]香港 - 中国-日本 沪日IEPL传输 Equinix-TY8 C04 Netflix
[2021-10-18 16:32:03,191][INFO][4513287680][config_parser.py:152]香港 - 中国-日本 沪日IEPL传输 Equinix-TY8 C05 Netflix
[2021-10-18 16:32:03,192][INFO][4513287680][config_parser.py:152]香港 - 中国-日本 沪日IEPL传输 Equinix-TY8 C06 Netflix
[2021-10-18 16:32:03,192][INFO][4513287680][config_parser.py:152]香港 - 中国-日本 沪日IEPL传输 Equinix-TY8 C07 Netflix
[2021-10-18 16:32:03,193][INFO][4513287680][config_parser.py:152]香港 - 中国-日本 沪日IEPL传输 Equinix-TY8 C08 Netflix
[2021-10-18 16:32:03,194][INFO][4513287680][config_parser.py:152]香港 - 中国-法国 IPLC C01
[2021-10-18 16:32:03,194][INFO][4513287680][config_parser.py:152]香港 - 中国-法国 IPLC C02
[2021-10-18 16:32:03,195][INFO][4513287680][config_parser.py:152]香港 - 中国-法国 IPLC C03
[2021-10-18 16:32:03,196][INFO][4513287680][config_parser.py:152]香港 - 中国-法国 IPLC C04
[2021-10-18 16:32:03,197][INFO][4513287680][config_parser.py:152]香港 - 中国-法国 IPLC C05
[2021-10-18 16:32:03,197][INFO][4513287680][config_parser.py:152]香港 - 中国-澳大利亚 IPLC 悉尼 C01
[2021-10-18 16:32:03,198][INFO][4513287680][config_parser.py:152]香港 - 中国-澳大利亚 IPLC 悉尼 C02
[2021-10-18 16:32:03,199][INFO][4513287680][config_parser.py:152]香港 - 中国-澳大利亚 IPLC 悉尼 C03
[2021-10-18 16:32:03,200][INFO][4513287680][config_parser.py:152]香港 - 中国-澳大利亚 IPLC 悉尼 C04
[2021-10-18 16:32:03,201][INFO][4513287680][config_parser.py:152]香港 - 中国-澳大利亚 IPLC 悉尼 C05
[2021-10-18 16:32:03,202][INFO][4513287680][config_parser.py:152]香港 - 中国-爱尔兰 IPLC C01
[2021-10-18 16:32:03,202][INFO][4513287680][config_parser.py:152]香港 - 中国-爱尔兰 IPLC C02
[2021-10-18 16:32:03,203][INFO][4513287680][config_parser.py:152]香港 - 中国-爱尔兰 IPLC C03
[2021-10-18 16:32:03,203][INFO][4513287680][config_parser.py:152]香港 - 中国-爱尔兰 IPLC C04
[2021-10-18 16:32:03,203][INFO][4513287680][config_parser.py:152]香港 - 中国-爱尔兰 IPLC C05
[2021-10-18 16:32:03,204][INFO][4513287680][config_parser.py:152]香港 - 中国-英国伦敦 IPLC BBC C01
[2021-10-18 16:32:03,204][INFO][4513287680][config_parser.py:152]香港 - 中国-英国伦敦 IPLC BBC C02
[2021-10-18 16:32:03,204][INFO][4513287680][config_parser.py:152]香港 - 中国-英国伦敦 IPLC BBC C03
[2021-10-18 16:32:03,205][INFO][4513287680][config_parser.py:152]香港 - 中国-英国伦敦 IPLC BBC C04
[2021-10-18 16:32:03,207][INFO][4513287680][config_parser.py:152]香港 - 中国-英国伦敦 IPLC BBC C05
[2021-10-18 16:32:03,207][INFO][4513287680][config_parser.py:152]香港 - 中国-英国伦敦 IPLC BBC C06
[2021-10-18 16:32:03,208][INFO][4513287680][config_parser.py:152]香港 - 中国-韩国 IEPL（三）A 1Gbps
[2021-10-18 16:32:03,209][INFO][4513287680][config_parser.py:152]香港 - 中国-韩国 IEPL（三）B 1Gbps
[2021-10-18 16:32:03,210][INFO][4513287680][config_parser.py:152]香港 - 中国-韩国 IEPL（三）C 1Gbps
[2021-10-18 16:32:03,211][INFO][4513287680][config_parser.py:152]香港 - 中国-韩国 IEPL（三）D 1Gbps
[2021-10-18 16:32:03,212][INFO][4513287680][config_parser.py:152]香港 - 中国-韩国 IEPL（三）E 1Gbps
[2021-10-18 16:32:03,215][INFO][4513287680][config_parser.py:152]香港 - 中国-香港 IEPL Equinix HK8 C 01 1Gbps Netflix HBO TVB
[2021-10-18 16:32:03,219][INFO][4513287680][config_parser.py:152]香港 - 中国-香港 IEPL Equinix HK8 C 02 1Gbps Netflix HBO TVB
[2021-10-18 16:32:03,226][INFO][4513287680][config_parser.py:152]香港 - 中国-香港 IEPL Equinix HK8 C 03 1Gbps Netflix HBO TVB
[2021-10-18 16:32:03,228][INFO][4513287680][config_parser.py:152]香港 - 中国-香港 IEPL Equinix HK8 C 04 1Gbps Netflix HBO TVB
[2021-10-18 16:32:03,229][INFO][4513287680][config_parser.py:152]香港 - 中国-香港 IEPL Equinix HK8 C 05 1Gbps Netflix HBO TVB
[2021-10-18 16:32:03,229][INFO][4513287680][config_parser.py:152]香港 - 中国-香港 IEPL Equinix HK8 C 06 1Gbps Netflix HBO TVB
[2021-10-18 16:32:03,233][INFO][4513287680][config_parser.py:152]香港 - 中国-香港 IEPL Equinix HK8 C 07 1Gbps Netflix HBO TVB
[2021-10-18 16:32:03,233][INFO][4513287680][config_parser.py:152]香港 - 中国-香港 IEPL Equinix HK8 C 08 1Gbps Netflix HBO TVB
[2021-10-18 16:32:03,234][INFO][4513287680][config_parser.py:152]香港 - 中国-香港 IEPL Equinix HK8 C 09 1Gbps Netflix HBO TVB
[2021-10-18 16:32:03,235][INFO][4513287680][config_parser.py:152]香港 - 中国-香港 IEPL Equinix HK8 C 10 1Gbps Netflix HBO TVB
[2021-10-18 16:32:03,235][INFO][4513287680][config_parser.py:152]香港 - 中国-香港 IPLC Equinix HK2 C 01 1Gbps Netflix HBO TVB
[2021-10-18 16:32:03,235][INFO][4513287680][config_parser.py:152]香港 - 中国-香港 IPLC Equinix HK2 C 02 1Gbps Netflix HBO TVB
[2021-10-18 16:32:03,236][INFO][4513287680][config_parser.py:152]香港 - 中国-香港 IPLC Equinix HK2 C 03 1Gbps Netflix HBO TVB
[2021-10-18 16:32:03,237][INFO][4513287680][config_parser.py:152]香港 - 中国-香港 IPLC Equinix HK2 C 04 1Gbps Netflix HBO TVB
[2021-10-18 16:32:03,240][INFO][4513287680][config_parser.py:152]香港 - 中国-香港 IPLC Equinix HK2 C 05 1Gbps Netflix HBO TVB
[2021-10-18 16:32:03,241][INFO][4513287680][config_parser.py:152]香港 - 中国-香港 IPLC Equinix HK2 C 06 1Gbps Netflix HBO TVB
[2021-10-18 16:32:03,242][INFO][4513287680][config_parser.py:152]香港 - 中国-香港 IPLC Equinix HK2 C 07 1Gbps Netflix HBO TVB
[2021-10-18 16:32:03,242][INFO][4513287680][config_parser.py:152]香港 - 中国-香港 IPLC Equinix HK2 C 08 1Gbps Netflix HBO TVB
[2021-10-18 16:32:03,243][INFO][4513287680][config_parser.py:152]香港 - 中国-香港 IPLC Equinix HK2 C 09 1Gbps Netflix HBO TVB
[2021-10-18 16:32:03,243][INFO][4513287680][config_parser.py:152]香港 - 中国-香港 IPLC Equinix HK2 C 10 1Gbps Netflix HBO TVB
[2021-10-18 16:32:03,244][INFO][4513287680][config_parser.py:152]香港 - 因V2ray重大漏洞问题，暂时下架全部V2节点。请使用ssr/ss连接方式进行使用。
[2021-10-18 16:32:03,245][INFO][4513287680][config_parser.py:152]香港 - 新加坡 Legacy Magic IEPL 中继 C01 Netflix
[2021-10-18 16:32:03,245][INFO][4513287680][config_parser.py:152]香港 - 新加坡 Legacy Magic IEPL 中继 C02 Netflix
[2021-10-18 16:32:03,246][INFO][4513287680][config_parser.py:152]香港 - 新加坡 Legacy Magic IEPL 中继 C03 Netflix
[2021-10-18 16:32:03,247][INFO][4513287680][config_parser.py:152]香港 - 新加坡 Legacy Magic IEPL 中继 C04 Netflix
[2021-10-18 16:32:03,249][INFO][4513287680][config_parser.py:152]香港 - 新加坡 Legacy Magic IEPL 中继 C05 Netflix
[2021-10-18 16:32:03,249][INFO][4513287680][config_parser.py:152]香港 - 新加坡 Magic IEPL 中继 C01 Netflix
[2021-10-18 16:32:03,250][INFO][4513287680][config_parser.py:152]香港 - 新加坡 Magic IEPL 中继 C02 Netflix
[2021-10-18 16:32:03,250][INFO][4513287680][config_parser.py:152]香港 - 新加坡 Magic IEPL 中继 C03 Netflix
[2021-10-18 16:32:03,251][INFO][4513287680][config_parser.py:152]香港 - 新加坡 Magic IEPL 中继 C04 Netflix
[2021-10-18 16:32:03,252][INFO][4513287680][config_parser.py:152]香港 - 新加坡 Magic IEPL 中继 C05 Netflix
[2021-10-18 16:32:03,252][INFO][4513287680][config_parser.py:152]香港 - 新加坡高级 IEPL 中继 C01 Netflix
[2021-10-18 16:32:03,254][INFO][4513287680][config_parser.py:152]香港 - 新加坡高级 IEPL 中继 C02 Netflix
[2021-10-18 16:32:03,256][INFO][4513287680][config_parser.py:152]香港 - 新加坡高级 IEPL 中继 C03 Netflix
[2021-10-18 16:32:03,257][INFO][4513287680][config_parser.py:152]香港 - 日本 ソフトバンク C01 500Mbps 1倍 Netflix
[2021-10-18 16:32:03,257][INFO][4513287680][config_parser.py:152]香港 - 日本 ソフトバンク C02 500Mbps 1倍 Netflix
[2021-10-18 16:32:03,258][INFO][4513287680][config_parser.py:152]香港 - 日本 ソフトバンク C03 500Mbps 1倍 Netflix
[2021-10-18 16:32:03,258][INFO][4513287680][config_parser.py:152]香港 - 日本 ソフトバンク C04 500Mbps 1倍 Netflix
[2021-10-18 16:32:03,258][INFO][4513287680][config_parser.py:152]香港 - 日本 ソフトバンク C05 500Mbps 1倍 Netflix
[2021-10-18 16:32:03,259][INFO][4513287680][config_parser.py:152]香港 - 日本 ソフトバンク C06 500Mbps 1倍 Netflix
[2021-10-18 16:32:03,259][INFO][4513287680][config_parser.py:152]香港 - 日本 ソフトバンク C07 500Mbps 1倍 Netflix
[2021-10-18 16:32:03,259][INFO][4513287680][config_parser.py:152]香港 - 日本 ソフトバンク C08 500Mbps 1倍 Netflix
[2021-10-18 16:32:03,260][INFO][4513287680][config_parser.py:152]香港 - 日本 ソフトバンク C09 500Mbps 1倍 Netflix
[2021-10-18 16:32:03,260][INFO][4513287680][config_parser.py:152]香港 - 日本 ソフトバンク C10 500Mbps 1倍 Netflix
[2021-10-18 16:32:03,263][INFO][4513287680][config_parser.py:152]香港 - 日本 ソフトバンク C11 500Mbps 1倍 Netflix
[2021-10-18 16:32:03,267][INFO][4513287680][config_parser.py:152]香港 - 日本 ソフトバンク C12 500Mbps 1倍 Netflix
[2021-10-18 16:32:03,268][INFO][4513287680][config_parser.py:152]香港 - 沪港 IEPL专线 港区TVB/HBO/Netflix解锁 C01
[2021-10-18 16:32:03,268][INFO][4513287680][config_parser.py:152]香港 - 沪港 IEPL专线 港区TVB/HBO/Netflix解锁 C02
[2021-10-18 16:32:03,268][INFO][4513287680][config_parser.py:152]香港 - 沪港 IEPL专线 港区TVB/HBO/Netflix解锁 C03
[2021-10-18 16:32:03,269][INFO][4513287680][config_parser.py:152]香港 - 沪港 IEPL专线 港区TVB/HBO/Netflix解锁 C04
[2021-10-18 16:32:03,270][INFO][4513287680][config_parser.py:152]香港 - 沪港 IEPL专线 港区TVB/HBO/Netflix解锁 C05
[2021-10-18 16:32:03,270][INFO][4513287680][config_parser.py:152]香港 - 精简 21
[2021-10-18 16:32:03,271][INFO][4513287680][config_parser.py:152]香港 - 精简 22
[2021-10-18 16:32:03,272][INFO][4513287680][config_parser.py:152]香港 - 精简 23
[2021-10-18 16:32:03,272][INFO][4513287680][config_parser.py:152]香港 - 精简 24
[2021-10-18 16:32:03,273][INFO][4513287680][config_parser.py:152]香港 - 精简 25
[2021-10-18 16:32:03,274][INFO][4513287680][config_parser.py:152]香港 - 精简 26
[2021-10-18 16:32:03,274][INFO][4513287680][config_parser.py:152]香港 - 精简 27
[2021-10-18 16:32:03,276][INFO][4513287680][config_parser.py:152]香港 - 精简 28
[2021-10-18 16:32:03,277][INFO][4513287680][config_parser.py:152]香港 - 精简 29
[2021-10-18 16:32:03,277][INFO][4513287680][config_parser.py:152]香港 - 美国实验性 IEPL 中继 C01
[2021-10-18 16:32:03,278][INFO][4513287680][config_parser.py:152]香港 - 美国实验性 IEPL 中继 C02
[2021-10-18 16:32:03,279][INFO][4513287680][config_parser.py:152]香港 - 美国实验性 IEPL 中继 C03
[2021-10-18 16:32:03,280][INFO][4513287680][config_parser.py:152]香港 - 美国实验性 IEPL 中继 C04
[2021-10-18 16:32:03,286][INFO][4513287680][config_parser.py:152]香港 - 美国实验性 IEPL 中继 C05
[2021-10-18 16:32:03,288][INFO][4513287680][config_parser.py:152]香港 - 美国高级 IEPL 中继 C01
[2021-10-18 16:32:03,289][INFO][4513287680][config_parser.py:152]香港 - 美国高级 IEPL 中继 C02
[2021-10-18 16:32:03,292][INFO][4513287680][config_parser.py:152]香港 - 美国高级 IEPL 中继 C03
[2021-10-18 16:32:03,292][INFO][4513287680][config_parser.py:152]香港 - 美国高级 IEPL 中继 C04
[2021-10-18 16:32:03,293][INFO][4513287680][config_parser.py:152]香港 - 美国高级 IEPL 中继 C05
[2021-10-18 16:32:03,293][INFO][4513287680][config_parser.py:152]香港 - 韩国 전라북도 전주시 商宽 C 01
[2021-10-18 16:32:03,294][INFO][4513287680][config_parser.py:152]香港 - 韩国 전라북도 전주시 商宽 C 02
[2021-10-18 16:32:03,294][INFO][4513287680][config_parser.py:152]香港 - 韩国 전라북도 전주시 商宽 C 03
[2021-10-18 16:32:03,295][INFO][4513287680][config_parser.py:152]香港 - 韩国 전라북도 전주시 商宽 C 04
[2021-10-18 16:32:03,296][INFO][4513287680][config_parser.py:152]香港 - 韩国 전라북도 전주시 商宽 C 05
[2021-10-18 16:32:03,296][INFO][4513287680][config_parser.py:152]香港 - 韩国 京畿道板桥 原生游戏解锁 C 01
[2021-10-18 16:32:03,299][INFO][4513287680][config_parser.py:152]香港 - 韩国 京畿道板桥 原生游戏解锁 C 02
[2021-10-18 16:32:03,300][INFO][4513287680][config_parser.py:152]香港 - 韩国 京畿道板桥 原生游戏解锁 C 03
[2021-10-18 16:32:03,300][INFO][4513287680][config_parser.py:152]香港 - 韩国 京畿道板桥 原生游戏解锁 C 04
[2021-10-18 16:32:03,300][INFO][4513287680][config_parser.py:152]香港 - 韩国 京畿道板桥 原生游戏解锁 C 05
[2021-10-18 16:32:03,301][INFO][4513287680][config_parser.py:152]香港 - 韩国 京畿道板桥 原生游戏解锁 C 06
[2021-10-18 16:32:03,301][INFO][4513287680][config_parser.py:152]香港 - 韩国 京畿道板桥 原生游戏解锁 C 07
[2021-10-18 16:32:03,302][INFO][4513287680][config_parser.py:152]香港 - 韩国 京畿道板桥 原生游戏解锁 C 08
[2021-10-18 16:32:03,302][INFO][4513287680][config_parser.py:152]香港 - 韩国 京畿道板桥 原生游戏解锁 C 09
[2021-10-18 16:32:03,303][INFO][4513287680][config_parser.py:152]香港 - 韩国 京畿道板桥 原生游戏解锁 C 10
[2021-10-18 16:32:03,305][INFO][4513287680][config_parser.py:152]香港 - 香港 油尖旺御金·国峯 名氣通電訊 C01
[2021-10-18 16:32:03,306][INFO][4513287680][config_parser.py:152]香港 - 香港 油尖旺御金·国峯 名氣通電訊 C02
[2021-10-18 16:32:03,307][INFO][4513287680][config_parser.py:152]香港 - 香港 油尖旺御金·国峯 名氣通電訊 C03
[2021-10-18 16:32:03,308][INFO][4513287680][config_parser.py:152]香港 - 香港 油尖旺御金·国峯 名氣通電訊 C04
[2021-10-18 16:32:03,309][INFO][4513287680][config_parser.py:152]香港 - 香港 油尖旺御金·国峯 名氣通電訊 C06
[2021-10-18 16:32:03,309][INFO][4513287680][config_parser.py:152]香港 - 香港 油尖旺御金·国峯 名氣通電訊 C07
[2021-10-18 16:32:03,310][INFO][4513287680][config_parser.py:152]香港 - 香港 油尖旺御金·国峯 名氣通電訊 C08
[2021-10-18 16:32:03,310][INFO][4513287680][config_parser.py:152]香港 - 香港 油尖旺御金·国峯 名氣通電訊 C09
[2021-10-18 16:32:03,311][INFO][4513287680][config_parser.py:152]香港 - 香港 油尖旺御金·国峯 環球全域電訊 C01
[2021-10-18 16:32:03,311][INFO][4513287680][config_parser.py:152]香港 - 香港 油尖旺御金·国峯 環球全域電訊 C02
[2021-10-18 16:32:03,311][INFO][4513287680][config_parser.py:152]香港 - 香港 油尖旺御金·国峯 環球全域電訊 C03
[2021-10-18 16:32:03,312][INFO][4513287680][config_parser.py:152]香港 - 香港 油尖旺御金·国峯 環球全域電訊 C04
[2021-10-18 16:32:03,313][INFO][4513287680][config_parser.py:152]香港 - 香港 油尖旺御金·国峯 環球全域電訊 C05
[2021-10-18 16:32:03,316][INFO][4513287680][config_parser.py:152]香港 - 香港 油尖旺御金·国峯 環球全域電訊 C06
[2021-10-18 16:32:03,316][INFO][4513287680][config_parser.py:152]香港 - 香港 油尖旺御金·国峯 環球全域電訊 C07
[2021-10-18 16:32:03,317][INFO][4513287680][config_parser.py:152]香港 - 香港 油尖旺御金·国峯 環球全域電訊 C08
[2021-10-18 16:32:03,317][INFO][4513287680][config_parser.py:152]香港 - 香港 油尖旺御金·国峯 環球全域電訊 C09
[2021-10-18 16:32:03,318][INFO][4513287680][config_parser.py:152]香港 - 香港 油尖旺御金·国峯 環球全域電訊 C10
[2021-10-18 16:32:03,332][INFO][4513287680][ssrspeed_core.py:165]198 node(s) will be test.
[2021-10-18 16:32:03,344][INFO][4513287680][speed_test.py:421]Test mode : speed and tcp ping.Test method : FAST.
[2021-10-18 16:32:03,344][INFO][4513287680][speed_test.py:242]Starting test 香港 - 1 加入用户群: https://t.me/joinchat/j_AxEbSzcX85NWI1 [1/198]
[2021-10-18 16:32:03,345][INFO][4513287680][platform_check.py:9]Platform Info : macOS-11.6-x86_64-i386-64bit
[2021-10-18 16:32:03,346][INFO][4513287680][platform_check.py:9]Platform Info : macOS-11.6-x86_64-i386-64bit
[2021-10-18 16:32:03,346][INFO][4513287680][platform_check.py:9]Platform Info : macOS-11.6-x86_64-i386-64bit
[2021-10-18 16:32:03,346][INFO][4513287680][platform_check.py:9]Platform Info : macOS-11.6-x86_64-i386-64bit
[2021-10-18 16:32:03,358][INFO][4513287680][client_shadowsocks.py:36]Starting Shadowsocks-libev with server 127.0.0.1:33400
[2021-10-18 16:32:04,363][INFO][4513287680][speed_test.py:276]Client started.
[2021-10-18 16:32:05,368][INFO][4513287680][geo_ip.py:46]Translating 127.0.0.1 to ipv4.
[2021-10-18 16:32:05,369][INFO][4513287680][geo_ip.py:63]Starting Geo IP.
[2021-10-18 16:32:05,389][ERROR][4513287680][geo_ip.py:76]Geo IP Failed.
Traceback (most recent call last):
  File "/Users/chinnsenn/.pyenv/versions/3.9.5/lib/python3.9/site-packages/urllib3/connectionpool.py", line 699, in urlopen
    httplib_response = self._make_request(
  File "/Users/chinnsenn/.pyenv/versions/3.9.5/lib/python3.9/site-packages/urllib3/connectionpool.py", line 382, in _make_request
    self._validate_conn(conn)
  File "/Users/chinnsenn/.pyenv/versions/3.9.5/lib/python3.9/site-packages/urllib3/connectionpool.py", line 1010, in _validate_conn
    conn.connect()
  File "/Users/chinnsenn/.pyenv/versions/3.9.5/lib/python3.9/site-packages/urllib3/connection.py", line 411, in connect
    self.sock = ssl_wrap_socket(
  File "/Users/chinnsenn/.pyenv/versions/3.9.5/lib/python3.9/site-packages/urllib3/util/ssl_.py", line 449, in ssl_wrap_socket
    ssl_sock = _ssl_wrap_socket_impl(
  File "/Users/chinnsenn/.pyenv/versions/3.9.5/lib/python3.9/site-packages/urllib3/util/ssl_.py", line 493, in _ssl_wrap_socket_impl
    return ssl_context.wrap_socket(sock, server_hostname=server_hostname)
  File "/Users/chinnsenn/.pyenv/versions/3.9.5/lib/python3.9/ssl.py", line 500, in wrap_socket
    return self.sslsocket_class._create(
  File "/Users/chinnsenn/.pyenv/versions/3.9.5/lib/python3.9/ssl.py", line 1040, in _create
    self.do_handshake()
  File "/Users/chinnsenn/.pyenv/versions/3.9.5/lib/python3.9/ssl.py", line 1309, in do_handshake
    self._sslobj.do_handshake()
ssl.SSLEOFError: EOF occurred in violation of protocol (_ssl.c:1129)

During handling of the above exception, another exception occurred:

Traceback (most recent call last):
  File "/Users/chinnsenn/.pyenv/versions/3.9.5/lib/python3.9/site-packages/requests/adapters.py", line 439, in send
    resp = conn.urlopen(
  File "/Users/chinnsenn/.pyenv/versions/3.9.5/lib/python3.9/site-packages/urllib3/connectionpool.py", line 755, in urlopen
    retries = retries.increment(
  File "/Users/chinnsenn/.pyenv/versions/3.9.5/lib/python3.9/site-packages/urllib3/util/retry.py", line 574, in increment
    raise MaxRetryError(_pool, url, error or ResponseError(cause))
urllib3.exceptions.MaxRetryError: SOCKSHTTPSConnectionPool(host='api.ip.sb', port=443): Max retries exceeded with url: /geoip/127.0.0.1 (Caused by SSLError(SSLEOFError(8, 'EOF occurred in violation of protocol (_ssl.c:1129)')))

During handling of the above exception, another exception occurred:

Traceback (most recent call last):
  File "/Users/chinnsenn/Developments.localized/PythonProjects/SSRSpeedN-Mod/ssrspeed/utils/geo_ip.py", line 66, in IPLoc
    rep = requests.get("https://api.ip.sb/geoip/{}".format(ip),proxies = {
  File "/Users/chinnsenn/.pyenv/versions/3.9.5/lib/python3.9/site-packages/requests/api.py", line 76, in get
    return request('get', url, params=params, **kwargs)
  File "/Users/chinnsenn/.pyenv/versions/3.9.5/lib/python3.9/site-packages/requests/api.py", line 61, in request
    return session.request(method=method, url=url, **kwargs)
  File "/Users/chinnsenn/.pyenv/versions/3.9.5/lib/python3.9/site-packages/requests/sessions.py", line 542, in request
    resp = self.send(prep, **send_kwargs)
  File "/Users/chinnsenn/.pyenv/versions/3.9.5/lib/python3.9/site-packages/requests/sessions.py", line 655, in send
    r = adapter.send(request, **kwargs)
  File "/Users/chinnsenn/.pyenv/versions/3.9.5/lib/python3.9/site-packages/requests/adapters.py", line 514, in send
    raise SSLError(e, request=request)
requests.exceptions.SSLError: SOCKSHTTPSConnectionPool(host='api.ip.sb', port=443): Max retries exceeded with url: /geoip/127.0.0.1 (Caused by SSLError(SSLEOFError(8, 'EOF occurred in violation of protocol (_ssl.c:1129)')))
[2021-10-18 16:32:05,396][INFO][4513287680][speed_test.py:111]Node inbound IP : 127.0.0.1, Geo : N/A Unknown City, N/A
[2021-10-18 16:32:05,396][INFO][4513287680][speed_test_methods.py:72]Testing latency to server.
[2021-10-18 16:32:05,397][ERROR][4513287680][ping.py:36]TCP Ping Exception:
Traceback (most recent call last):
  File "/Users/chinnsenn/Developments.localized/PythonProjects/SSRSpeedN-Mod/ssrspeed/speed_test/test_methods/ping.py", line 24, in tcp_ping
    s.connect((host,port))
ConnectionRefusedError: [Errno 61] Connection refused
[2021-10-18 16:32:05,399][ERROR][4513287680][ping.py:36]TCP Ping Exception:
Traceback (most recent call last):
  File "/Users/chinnsenn/Developments.localized/PythonProjects/SSRSpeedN-Mod/ssrspeed/speed_test/test_methods/ping.py", line 24, in tcp_ping
    s.connect((host,port))
ConnectionRefusedError: [Errno 61] Connection refused
[2021-10-18 16:32:05,399][ERROR][4513287680][ping.py:36]TCP Ping Exception:
Traceback (most recent call last):
  File "/Users/chinnsenn/Developments.localized/PythonProjects/SSRSpeedN-Mod/ssrspeed/speed_test/test_methods/ping.py", line 24, in tcp_ping
    s.connect((host,port))
ConnectionRefusedError: [Errno 61] Connection refused
[2021-10-18 16:32:06,405][INFO][4513287680][geo_ip.py:63]Starting Geo IP.
[2021-10-18 16:32:06,422][ERROR][4513287680][geo_ip.py:76]Geo IP Failed.
Traceback (most recent call last):
  File "/Users/chinnsenn/.pyenv/versions/3.9.5/lib/python3.9/site-packages/urllib3/connectionpool.py", line 699, in urlopen
    httplib_response = self._make_request(
  File "/Users/chinnsenn/.pyenv/versions/3.9.5/lib/python3.9/site-packages/urllib3/connectionpool.py", line 382, in _make_request
    self._validate_conn(conn)
  File "/Users/chinnsenn/.pyenv/versions/3.9.5/lib/python3.9/site-packages/urllib3/connectionpool.py", line 1010, in _validate_conn
    conn.connect()
  File "/Users/chinnsenn/.pyenv/versions/3.9.5/lib/python3.9/site-packages/urllib3/connection.py", line 411, in connect
    self.sock = ssl_wrap_socket(
  File "/Users/chinnsenn/.pyenv/versions/3.9.5/lib/python3.9/site-packages/urllib3/util/ssl_.py", line 449, in ssl_wrap_socket
    ssl_sock = _ssl_wrap_socket_impl(
  File "/Users/chinnsenn/.pyenv/versions/3.9.5/lib/python3.9/site-packages/urllib3/util/ssl_.py", line 493, in _ssl_wrap_socket_impl
    return ssl_context.wrap_socket(sock, server_hostname=server_hostname)
  File "/Users/chinnsenn/.pyenv/versions/3.9.5/lib/python3.9/ssl.py", line 500, in wrap_socket
    return self.sslsocket_class._create(
  File "/Users/chinnsenn/.pyenv/versions/3.9.5/lib/python3.9/ssl.py", line 1040, in _create
    self.do_handshake()
  File "/Users/chinnsenn/.pyenv/versions/3.9.5/lib/python3.9/ssl.py", line 1309, in do_handshake
    self._sslobj.do_handshake()
ssl.SSLEOFError: EOF occurred in violation of protocol (_ssl.c:1129)

During handling of the above exception, another exception occurred:

Traceback (most recent call last):
  File "/Users/chinnsenn/.pyenv/versions/3.9.5/lib/python3.9/site-packages/requests/adapters.py", line 439, in send
    resp = conn.urlopen(
  File "/Users/chinnsenn/.pyenv/versions/3.9.5/lib/python3.9/site-packages/urllib3/connectionpool.py", line 755, in urlopen
    retries = retries.increment(
  File "/Users/chinnsenn/.pyenv/versions/3.9.5/lib/python3.9/site-packages/urllib3/util/retry.py", line 574, in increment
    raise MaxRetryError(_pool, url, error or ResponseError(cause))
urllib3.exceptions.MaxRetryError: SOCKSHTTPSConnectionPool(host='api.ip.sb', port=443): Max retries exceeded with url: /geoip/ (Caused by SSLError(SSLEOFError(8, 'EOF occurred in violation of protocol (_ssl.c:1129)')))

During handling of the above exception, another exception occurred:

Traceback (most recent call last):
  File "/Users/chinnsenn/Developments.localized/PythonProjects/SSRSpeedN-Mod/ssrspeed/utils/geo_ip.py", line 66, in IPLoc
    rep = requests.get("https://api.ip.sb/geoip/{}".format(ip),proxies = {
  File "/Users/chinnsenn/.pyenv/versions/3.9.5/lib/python3.9/site-packages/requests/api.py", line 76, in get
    return request('get', url, params=params, **kwargs)
  File "/Users/chinnsenn/.pyenv/versions/3.9.5/lib/python3.9/site-packages/requests/api.py", line 61, in request
    return session.request(method=method, url=url, **kwargs)
  File "/Users/chinnsenn/.pyenv/versions/3.9.5/lib/python3.9/site-packages/requests/sessions.py", line 542, in request
    resp = self.send(prep, **send_kwargs)
  File "/Users/chinnsenn/.pyenv/versions/3.9.5/lib/python3.9/site-packages/requests/sessions.py", line 655, in send
    r = adapter.send(request, **kwargs)
  File "/Users/chinnsenn/.pyenv/versions/3.9.5/lib/python3.9/site-packages/requests/adapters.py", line 514, in send
    raise SSLError(e, request=request)
requests.exceptions.SSLError: SOCKSHTTPSConnectionPool(host='api.ip.sb', port=443): Max retries exceeded with url: /geoip/ (Caused by SSLError(SSLEOFError(8, 'EOF occurred in violation of protocol (_ssl.c:1129)')))
[2021-10-18 16:32:06,426][INFO][4513287680][speed_test.py:127]Node outbound IP : N/A, Geo : N/A Unknown City, N/A
[2021-10-18 16:32:06,426][INFO][4513287680][speed_test.py:135]Performing netflix test LOCAL_PORT: 1087.
[2021-10-18 16:32:06,443][ERROR][4513287680][speed_test.py:177]代理服务器连接异常：(MaxRetryError("SOCKSHTTPSConnectionPool(host='www.netflix.com', port=443): Max retries exceeded with url: /title/70242311 (Caused by SSLError(SSLEOFError(8, 'EOF occurred in violation of protocol (_ssl.c:1129)')))"),)
[2021-10-18 16:32:06,446][INFO][4513287680][platform_check.py:9]Platform Info : macOS-11.6-x86_64-i386-64bit
[2021-10-18 16:32:06,448][INFO][4513287680][base_client.py:51]Client terminated.
[2021-10-18 16:32:07,456][INFO][4513287680][speed_test.py:242]Starting test 香港 - ASYNCHRONOUS TRANSFERMODE 永久虚通路连接PVCC C01 [2/198]
[2021-10-18 16:32:07,457][INFO][4513287680][platform_check.py:9]Platform Info : macOS-11.6-x86_64-i386-64bit
[2021-10-18 16:32:07,457][INFO][4513287680][platform_check.py:9]Platform Info : macOS-11.6-x86_64-i386-64bit
[2021-10-18 16:32:07,458][INFO][4513287680][platform_check.py:9]Platform Info : macOS-11.6-x86_64-i386-64bit
[2021-10-18 16:32:07,458][INFO][4513287680][platform_check.py:9]Platform Info : macOS-11.6-x86_64-i386-64bit
[2021-10-18 16:32:07,486][INFO][4513287680][client_shadowsocks.py:36]Starting Shadowsocks-libev with server pvcc01.cathayroute.com:33400
[2021-10-18 16:32:08,493][INFO][4513287680][speed_test.py:276]Client started.
[2021-10-18 16:32:09,500][INFO][4513287680][geo_ip.py:46]Translating pvcc01.cathayroute.com to ipv4.
[2021-10-18 16:32:09,502][INFO][4513287680][geo_ip.py:63]Starting Geo IP.
[2021-10-18 16:32:10,794][INFO][4513287680][speed_test.py:111]Node inbound IP : 162.14.11.142, Geo : United States Unknown City, Tencent cloud computing
[2021-10-18 16:32:10,794][INFO][4513287680][speed_test_methods.py:72]Testing latency to server.
[2021-10-18 16:32:12,285][INFO][4513287680][speed_test_methods.py:68]Testing latency to google.
[2021-10-18 16:32:14,858][INFO][4513287680][geo_ip.py:63]Starting Geo IP.
[2021-10-18 16:32:16,044][INFO][4513287680][speed_test.py:127]Node outbound IP : 210.0.159.46, Geo : Hong Kong Central, HGC Broadband
[2021-10-18 16:32:16,045][INFO][4513287680][speed_test.py:135]Performing netflix test LOCAL_PORT: 1087.
[2021-10-18 16:32:19,116][INFO][4513287680][speed_test.py:153]Netflix IP : 210.0.159.46
[2021-10-18 16:32:21,354][INFO][4513287680][speed_test.py:170]Netflix test result: 原生解锁.
[2021-10-18 16:32:21,354][INFO][4513287680][speed_test.py:218]Performing UDP NAT Type Test
[2021-10-18 16:32:22,543][INFO][4513287680][speed_test_methods.py:44]Starting speed test with FAST
[2021-10-18 16:32:22,543][WARNING][4513287680][speed_test.py:374]Re-testing node.
[2021-10-18 16:32:22,543][INFO][4513287680][speed_test_methods.py:44]Starting speed test with FAST
[2021-10-18 16:32:22,543][INFO][4513287680][speed_test.py:386][香港] - [ASYNCHRONOUS TRANSFERMODE 永久虚通路连接PVCC C01] - Loss: [0.00%] - TCP Ping: [48.00] - Google Loss: [0.00%] - Google Ping: [256.00] - AvgStSpeed: [0.00MB/s] - AvgMtSpeed: [0.00MB/s] - NAT Type: Full-cone NAT - Internal End: 10.10.20.57:54320 - Public End: 210.0.159.46:41388
[2021-10-18 16:32:22,543][INFO][4513287680][platform_check.py:9]Platform Info : macOS-11.6-x86_64-i386-64bit
[2021-10-18 16:32:22,543][INFO][4513287680][base_client.py:51]Client terminated.
[2021-10-18 16:32:23,548][INFO][4513287680][speed_test.py:242]Starting test 香港 - IPV6 俄罗斯 C01 [3/198]
[2021-10-18 16:32:23,548][INFO][4513287680][platform_check.py:9]Platform Info : macOS-11.6-x86_64-i386-64bit
[2021-10-18 16:32:23,549][INFO][4513287680][platform_check.py:9]Platform Info : macOS-11.6-x86_64-i386-64bit
[2021-10-18 16:32:23,549][INFO][4513287680][platform_check.py:9]Platform Info : macOS-11.6-x86_64-i386-64bit
[2021-10-18 16:32:23,550][INFO][4513287680][platform_check.py:9]Platform Info : macOS-11.6-x86_64-i386-64bit
[2021-10-18 16:32:23,555][INFO][4513287680][client_shadowsocks.py:36]Starting Shadowsocks-libev with server 2a00:b700:2::8:e6:33400
[2021-10-18 16:32:24,565][INFO][4513287680][speed_test.py:276]Client started.
[2021-10-18 16:32:25,570][INFO][4513287680][geo_ip.py:46]Translating 2a00:b700:2::8:e6 to ipv4.
[2021-10-18 16:32:25,570][ERROR][4513287680][geo_ip.py:54]Translate 2a00:b700:2::8:e6 to ipv4 failed.
Traceback (most recent call last):
  File "/Users/chinnsenn/Developments.localized/PythonProjects/SSRSpeedN-Mod/ssrspeed/utils/geo_ip.py", line 51, in domain2ip
    ip = socket.gethostbyname(domain)
socket.gaierror: [Errno 8] nodename nor servname provided, or not known
[2021-10-18 16:32:25,570][ERROR][4513287680][geo_ip.py:61]Invalid IP : N/A
[2021-10-18 16:32:25,571][INFO][4513287680][speed_test.py:111]Node inbound IP : N/A, Geo : N/A Unknown City, N/A
[2021-10-18 16:32:25,571][INFO][4513287680][speed_test_methods.py:72]Testing latency to server.
[2021-10-18 16:32:25,571][ERROR][4513287680][ping.py:36]TCP Ping Exception:
Traceback (most recent call last):
  File "/Users/chinnsenn/Developments.localized/PythonProjects/SSRSpeedN-Mod/ssrspeed/speed_test/test_methods/ping.py", line 24, in tcp_ping
    s.connect((host,port))
socket.gaierror: [Errno 8] nodename nor servname provided, or not known
[2021-10-18 16:32:25,572][ERROR][4513287680][ping.py:36]TCP Ping Exception:
Traceback (most recent call last):
  File "/Users/chinnsenn/Developments.localized/PythonProjects/SSRSpeedN-Mod/ssrspeed/speed_test/test_methods/ping.py", line 24, in tcp_ping
    s.connect((host,port))
socket.gaierror: [Errno 8] nodename nor servname provided, or not known
[2021-10-18 16:32:25,572][ERROR][4513287680][ping.py:36]TCP Ping Exception:
Traceback (most recent call last):
  File "/Users/chinnsenn/Developments.localized/PythonProjects/SSRSpeedN-Mod/ssrspeed/speed_test/test_methods/ping.py", line 24, in tcp_ping
    s.connect((host,port))
socket.gaierror: [Errno 8] nodename nor servname provided, or not known
[2021-10-18 16:32:26,577][INFO][4513287680][geo_ip.py:63]Starting Geo IP.
[2021-10-18 16:32:26,603][ERROR][4513287680][geo_ip.py:76]Geo IP Failed.
Traceback (most recent call last):
  File "/Users/chinnsenn/.pyenv/versions/3.9.5/lib/python3.9/site-packages/urllib3/connectionpool.py", line 699, in urlopen
    httplib_response = self._make_request(
  File "/Users/chinnsenn/.pyenv/versions/3.9.5/lib/python3.9/site-packages/urllib3/connectionpool.py", line 382, in _make_request
    self._validate_conn(conn)
  File "/Users/chinnsenn/.pyenv/versions/3.9.5/lib/python3.9/site-packages/urllib3/connectionpool.py", line 1010, in _validate_conn
    conn.connect()
  File "/Users/chinnsenn/.pyenv/versions/3.9.5/lib/python3.9/site-packages/urllib3/connection.py", line 411, in connect
    self.sock = ssl_wrap_socket(
  File "/Users/chinnsenn/.pyenv/versions/3.9.5/lib/python3.9/site-packages/urllib3/util/ssl_.py", line 449, in ssl_wrap_socket
    ssl_sock = _ssl_wrap_socket_impl(
  File "/Users/chinnsenn/.pyenv/versions/3.9.5/lib/python3.9/site-packages/urllib3/util/ssl_.py", line 493, in _ssl_wrap_socket_impl
    return ssl_context.wrap_socket(sock, server_hostname=server_hostname)
  File "/Users/chinnsenn/.pyenv/versions/3.9.5/lib/python3.9/ssl.py", line 500, in wrap_socket
    return self.sslsocket_class._create(
  File "/Users/chinnsenn/.pyenv/versions/3.9.5/lib/python3.9/ssl.py", line 1040, in _create
    self.do_handshake()
  File "/Users/chinnsenn/.pyenv/versions/3.9.5/lib/python3.9/ssl.py", line 1309, in do_handshake
    self._sslobj.do_handshake()
ssl.SSLEOFError: EOF occurred in violation of protocol (_ssl.c:1129)

During handling of the above exception, another exception occurred:

Traceback (most recent call last):
  File "/Users/chinnsenn/.pyenv/versions/3.9.5/lib/python3.9/site-packages/requests/adapters.py", line 439, in send
    resp = conn.urlopen(
  File "/Users/chinnsenn/.pyenv/versions/3.9.5/lib/python3.9/site-packages/urllib3/connectionpool.py", line 755, in urlopen
    retries = retries.increment(
  File "/Users/chinnsenn/.pyenv/versions/3.9.5/lib/python3.9/site-packages/urllib3/util/retry.py", line 574, in increment
    raise MaxRetryError(_pool, url, error or ResponseError(cause))
urllib3.exceptions.MaxRetryError: SOCKSHTTPSConnectionPool(host='api.ip.sb', port=443): Max retries exceeded with url: /geoip/ (Caused by SSLError(SSLEOFError(8, 'EOF occurred in violation of protocol (_ssl.c:1129)')))

During handling of the above exception, another exception occurred:

Traceback (most recent call last):
  File "/Users/chinnsenn/Developments.localized/PythonProjects/SSRSpeedN-Mod/ssrspeed/utils/geo_ip.py", line 66, in IPLoc
    rep = requests.get("https://api.ip.sb/geoip/{}".format(ip),proxies = {
  File "/Users/chinnsenn/.pyenv/versions/3.9.5/lib/python3.9/site-packages/requests/api.py", line 76, in get
    return request('get', url, params=params, **kwargs)
  File "/Users/chinnsenn/.pyenv/versions/3.9.5/lib/python3.9/site-packages/requests/api.py", line 61, in request
    return session.request(method=method, url=url, **kwargs)
  File "/Users/chinnsenn/.pyenv/versions/3.9.5/lib/python3.9/site-packages/requests/sessions.py", line 542, in request
    resp = self.send(prep, **send_kwargs)
  File "/Users/chinnsenn/.pyenv/versions/3.9.5/lib/python3.9/site-packages/requests/sessions.py", line 655, in send
    r = adapter.send(request, **kwargs)
  File "/Users/chinnsenn/.pyenv/versions/3.9.5/lib/python3.9/site-packages/requests/adapters.py", line 514, in send
    raise SSLError(e, request=request)
requests.exceptions.SSLError: SOCKSHTTPSConnectionPool(host='api.ip.sb', port=443): Max retries exceeded with url: /geoip/ (Caused by SSLError(SSLEOFError(8, 'EOF occurred in violation of protocol (_ssl.c:1129)')))
[2021-10-18 16:32:26,607][INFO][4513287680][speed_test.py:127]Node outbound IP : N/A, Geo : N/A Unknown City, N/A
[2021-10-18 16:32:26,608][INFO][4513287680][speed_test.py:135]Performing netflix test LOCAL_PORT: 1087.
[2021-10-18 16:32:26,624][ERROR][4513287680][speed_test.py:177]代理服务器连接异常：(MaxRetryError("SOCKSHTTPSConnectionPool(host='www.netflix.com', port=443): Max retries exceeded with url: /title/70242311 (Caused by SSLError(SSLEOFError(8, 'EOF occurred in violation of protocol (_ssl.c:1129)')))"),)
[2021-10-18 16:32:26,627][INFO][4513287680][platform_check.py:9]Platform Info : macOS-11.6-x86_64-i386-64bit
[2021-10-18 16:32:26,628][INFO][4513287680][base_client.py:51]Client terminated.
[2021-10-18 16:32:27,633][INFO][4513287680][speed_test.py:242]Starting test 香港 - IPV6 加拿大 C01 [4/198]
[2021-10-18 16:32:27,633][INFO][4513287680][platform_check.py:9]Platform Info : macOS-11.6-x86_64-i386-64bit
[2021-10-18 16:32:27,634][INFO][4513287680][platform_check.py:9]Platform Info : macOS-11.6-x86_64-i386-64bit
[2021-10-18 16:32:27,634][INFO][4513287680][platform_check.py:9]Platform Info : macOS-11.6-x86_64-i386-64bit
[2021-10-18 16:32:27,634][INFO][4513287680][platform_check.py:9]Platform Info : macOS-11.6-x86_64-i386-64bit
[2021-10-18 16:32:27,638][INFO][4513287680][client_shadowsocks.py:36]Starting Shadowsocks-libev with server 2600:1f11:f6f:2300:60be:4248:6c6:96bd:33400
[2021-10-18 16:32:28,643][INFO][4513287680][speed_test.py:276]Client started.
[2021-10-18 16:32:29,650][INFO][4513287680][geo_ip.py:46]Translating 2600:1f11:f6f:2300:60be:4248:6c6:96bd to ipv4.
[2021-10-18 16:32:29,650][ERROR][4513287680][geo_ip.py:54]Translate 2600:1f11:f6f:2300:60be:4248:6c6:96bd to ipv4 failed.
Traceback (most recent call last):
  File "/Users/chinnsenn/Developments.localized/PythonProjects/SSRSpeedN-Mod/ssrspeed/utils/geo_ip.py", line 51, in domain2ip
    ip = socket.gethostbyname(domain)
socket.gaierror: [Errno 8] nodename nor servname provided, or not known
[2021-10-18 16:32:29,651][ERROR][4513287680][geo_ip.py:61]Invalid IP : N/A
[2021-10-18 16:32:29,651][INFO][4513287680][speed_test.py:111]Node inbound IP : N/A, Geo : N/A Unknown City, N/A
[2021-10-18 16:32:29,652][INFO][4513287680][speed_test_methods.py:72]Testing latency to server.
[2021-10-18 16:32:29,652][ERROR][4513287680][ping.py:36]TCP Ping Exception:
Traceback (most recent call last):
  File "/Users/chinnsenn/Developments.localized/PythonProjects/SSRSpeedN-Mod/ssrspeed/speed_test/test_methods/ping.py", line 24, in tcp_ping
    s.connect((host,port))
socket.gaierror: [Errno 8] nodename nor servname provided, or not known
[2021-10-18 16:32:29,653][ERROR][4513287680][ping.py:36]TCP Ping Exception:
Traceback (most recent call last):
  File "/Users/chinnsenn/Developments.localized/PythonProjects/SSRSpeedN-Mod/ssrspeed/speed_test/test_methods/ping.py", line 24, in tcp_ping
    s.connect((host,port))
socket.gaierror: [Errno 8] nodename nor servname provided, or not known
[2021-10-18 16:32:29,654][ERROR][4513287680][ping.py:36]TCP Ping Exception:
Traceback (most recent call last):
  File "/Users/chinnsenn/Developments.localized/PythonProjects/SSRSpeedN-Mod/ssrspeed/speed_test/test_methods/ping.py", line 24, in tcp_ping
    s.connect((host,port))
socket.gaierror: [Errno 8] nodename nor servname provided, or not known
[2021-10-18 16:32:30,659][INFO][4513287680][geo_ip.py:63]Starting Geo IP.
[2021-10-18 16:32:30,681][ERROR][4513287680][geo_ip.py:76]Geo IP Failed.
Traceback (most recent call last):
  File "/Users/chinnsenn/.pyenv/versions/3.9.5/lib/python3.9/site-packages/urllib3/connectionpool.py", line 699, in urlopen
    httplib_response = self._make_request(
  File "/Users/chinnsenn/.pyenv/versions/3.9.5/lib/python3.9/site-packages/urllib3/connectionpool.py", line 382, in _make_request
    self._validate_conn(conn)
  File "/Users/chinnsenn/.pyenv/versions/3.9.5/lib/python3.9/site-packages/urllib3/connectionpool.py", line 1010, in _validate_conn
    conn.connect()
  File "/Users/chinnsenn/.pyenv/versions/3.9.5/lib/python3.9/site-packages/urllib3/connection.py", line 411, in connect
    self.sock = ssl_wrap_socket(
  File "/Users/chinnsenn/.pyenv/versions/3.9.5/lib/python3.9/site-packages/urllib3/util/ssl_.py", line 449, in ssl_wrap_socket
    ssl_sock = _ssl_wrap_socket_impl(
  File "/Users/chinnsenn/.pyenv/versions/3.9.5/lib/python3.9/site-packages/urllib3/util/ssl_.py", line 493, in _ssl_wrap_socket_impl
    return ssl_context.wrap_socket(sock, server_hostname=server_hostname)
  File "/Users/chinnsenn/.pyenv/versions/3.9.5/lib/python3.9/ssl.py", line 500, in wrap_socket
    return self.sslsocket_class._create(
  File "/Users/chinnsenn/.pyenv/versions/3.9.5/lib/python3.9/ssl.py", line 1040, in _create
    self.do_handshake()
  File "/Users/chinnsenn/.pyenv/versions/3.9.5/lib/python3.9/ssl.py", line 1309, in do_handshake
    self._sslobj.do_handshake()
ssl.SSLEOFError: EOF occurred in violation of protocol (_ssl.c:1129)

During handling of the above exception, another exception occurred:

Traceback (most recent call last):
  File "/Users/chinnsenn/.pyenv/versions/3.9.5/lib/python3.9/site-packages/requests/adapters.py", line 439, in send
    resp = conn.urlopen(
  File "/Users/chinnsenn/.pyenv/versions/3.9.5/lib/python3.9/site-packages/urllib3/connectionpool.py", line 755, in urlopen
    retries = retries.increment(
  File "/Users/chinnsenn/.pyenv/versions/3.9.5/lib/python3.9/site-packages/urllib3/util/retry.py", line 574, in increment
    raise MaxRetryError(_pool, url, error or ResponseError(cause))
urllib3.exceptions.MaxRetryError: SOCKSHTTPSConnectionPool(host='api.ip.sb', port=443): Max retries exceeded with url: /geoip/ (Caused by SSLError(SSLEOFError(8, 'EOF occurred in violation of protocol (_ssl.c:1129)')))

During handling of the above exception, another exception occurred:

Traceback (most recent call last):
  File "/Users/chinnsenn/Developments.localized/PythonProjects/SSRSpeedN-Mod/ssrspeed/utils/geo_ip.py", line 66, in IPLoc
    rep = requests.get("https://api.ip.sb/geoip/{}".format(ip),proxies = {
  File "/Users/chinnsenn/.pyenv/versions/3.9.5/lib/python3.9/site-packages/requests/api.py", line 76, in get
    return request('get', url, params=params, **kwargs)
  File "/Users/chinnsenn/.pyenv/versions/3.9.5/lib/python3.9/site-packages/requests/api.py", line 61, in request
    return session.request(method=method, url=url, **kwargs)
  File "/Users/chinnsenn/.pyenv/versions/3.9.5/lib/python3.9/site-packages/requests/sessions.py", line 542, in request
    resp = self.send(prep, **send_kwargs)
  File "/Users/chinnsenn/.pyenv/versions/3.9.5/lib/python3.9/site-packages/requests/sessions.py", line 655, in send
    r = adapter.send(request, **kwargs)
  File "/Users/chinnsenn/.pyenv/versions/3.9.5/lib/python3.9/site-packages/requests/adapters.py", line 514, in send
    raise SSLError(e, request=request)
requests.exceptions.SSLError: SOCKSHTTPSConnectionPool(host='api.ip.sb', port=443): Max retries exceeded with url: /geoip/ (Caused by SSLError(SSLEOFError(8, 'EOF occurred in violation of protocol (_ssl.c:1129)')))
[2021-10-18 16:32:30,685][INFO][4513287680][speed_test.py:127]Node outbound IP : N/A, Geo : N/A Unknown City, N/A
[2021-10-18 16:32:30,686][INFO][4513287680][speed_test.py:135]Performing netflix test LOCAL_PORT: 1087.
[2021-10-18 16:32:30,701][ERROR][4513287680][speed_test.py:177]代理服务器连接异常：(MaxRetryError("SOCKSHTTPSConnectionPool(host='www.netflix.com', port=443): Max retries exceeded with url: /title/70242311 (Caused by SSLError(SSLEOFError(8, 'EOF occurred in violation of protocol (_ssl.c:1129)')))"),)
[2021-10-18 16:32:30,703][INFO][4513287680][platform_check.py:9]Platform Info : macOS-11.6-x86_64-i386-64bit
[2021-10-18 16:32:30,703][INFO][4513287680][base_client.py:51]Client terminated.
[2021-10-18 16:32:31,708][INFO][4513287680][speed_test.py:242]Starting test 香港 - IPV6 日本 C01 [5/198]
[2021-10-18 16:32:31,708][INFO][4513287680][platform_check.py:9]Platform Info : macOS-11.6-x86_64-i386-64bit
[2021-10-18 16:32:31,710][INFO][4513287680][platform_check.py:9]Platform Info : macOS-11.6-x86_64-i386-64bit
[2021-10-18 16:32:31,710][INFO][4513287680][platform_check.py:9]Platform Info : macOS-11.6-x86_64-i386-64bit
[2021-10-18 16:32:31,710][INFO][4513287680][platform_check.py:9]Platform Info : macOS-11.6-x86_64-i386-64bit
[2021-10-18 16:32:31,716][INFO][4513287680][client_shadowsocks.py:36]Starting Shadowsocks-libev with server 2401:2500:204:1102:153:127:9:202:33400
[2021-10-18 16:32:32,721][INFO][4513287680][speed_test.py:276]Client started.
[2021-10-18 16:32:33,725][INFO][4513287680][geo_ip.py:46]Translating 2401:2500:204:1102:153:127:9:202 to ipv4.
[2021-10-18 16:32:33,726][ERROR][4513287680][geo_ip.py:54]Translate 2401:2500:204:1102:153:127:9:202 to ipv4 failed.
Traceback (most recent call last):
  File "/Users/chinnsenn/Developments.localized/PythonProjects/SSRSpeedN-Mod/ssrspeed/utils/geo_ip.py", line 51, in domain2ip
    ip = socket.gethostbyname(domain)
socket.gaierror: [Errno 8] nodename nor servname provided, or not known
[2021-10-18 16:32:33,727][ERROR][4513287680][geo_ip.py:61]Invalid IP : N/A
[2021-10-18 16:32:33,727][INFO][4513287680][speed_test.py:111]Node inbound IP : N/A, Geo : N/A Unknown City, N/A
[2021-10-18 16:32:33,727][INFO][4513287680][speed_test_methods.py:72]Testing latency to server.
[2021-10-18 16:32:33,727][ERROR][4513287680][ping.py:36]TCP Ping Exception:
Traceback (most recent call last):
  File "/Users/chinnsenn/Developments.localized/PythonProjects/SSRSpeedN-Mod/ssrspeed/speed_test/test_methods/ping.py", line 24, in tcp_ping
    s.connect((host,port))
socket.gaierror: [Errno 8] nodename nor servname provided, or not known
[2021-10-18 16:32:33,728][ERROR][4513287680][ping.py:36]TCP Ping Exception:
Traceback (most recent call last):
  File "/Users/chinnsenn/Developments.localized/PythonProjects/SSRSpeedN-Mod/ssrspeed/speed_test/test_methods/ping.py", line 24, in tcp_ping
    s.connect((host,port))
socket.gaierror: [Errno 8] nodename nor servname provided, or not known
[2021-10-18 16:32:33,728][ERROR][4513287680][ping.py:36]TCP Ping Exception:
Traceback (most recent call last):
  File "/Users/chinnsenn/Developments.localized/PythonProjects/SSRSpeedN-Mod/ssrspeed/speed_test/test_methods/ping.py", line 24, in tcp_ping
    s.connect((host,port))
socket.gaierror: [Errno 8] nodename nor servname provided, or not known
[2021-10-18 16:32:34,730][INFO][4513287680][geo_ip.py:63]Starting Geo IP.
[2021-10-18 16:32:34,749][ERROR][4513287680][geo_ip.py:76]Geo IP Failed.
Traceback (most recent call last):
  File "/Users/chinnsenn/.pyenv/versions/3.9.5/lib/python3.9/site-packages/urllib3/connectionpool.py", line 699, in urlopen
    httplib_response = self._make_request(
  File "/Users/chinnsenn/.pyenv/versions/3.9.5/lib/python3.9/site-packages/urllib3/connectionpool.py", line 382, in _make_request
    self._validate_conn(conn)
  File "/Users/chinnsenn/.pyenv/versions/3.9.5/lib/python3.9/site-packages/urllib3/connectionpool.py", line 1010, in _validate_conn
    conn.connect()
  File "/Users/chinnsenn/.pyenv/versions/3.9.5/lib/python3.9/site-packages/urllib3/connection.py", line 411, in connect
    self.sock = ssl_wrap_socket(
  File "/Users/chinnsenn/.pyenv/versions/3.9.5/lib/python3.9/site-packages/urllib3/util/ssl_.py", line 449, in ssl_wrap_socket
    ssl_sock = _ssl_wrap_socket_impl(
  File "/Users/chinnsenn/.pyenv/versions/3.9.5/lib/python3.9/site-packages/urllib3/util/ssl_.py", line 493, in _ssl_wrap_socket_impl
    return ssl_context.wrap_socket(sock, server_hostname=server_hostname)
  File "/Users/chinnsenn/.pyenv/versions/3.9.5/lib/python3.9/ssl.py", line 500, in wrap_socket
    return self.sslsocket_class._create(
  File "/Users/chinnsenn/.pyenv/versions/3.9.5/lib/python3.9/ssl.py", line 1040, in _create
    self.do_handshake()
  File "/Users/chinnsenn/.pyenv/versions/3.9.5/lib/python3.9/ssl.py", line 1309, in do_handshake
    self._sslobj.do_handshake()
ssl.SSLEOFError: EOF occurred in violation of protocol (_ssl.c:1129)

During handling of the above exception, another exception occurred:

Traceback (most recent call last):
  File "/Users/chinnsenn/.pyenv/versions/3.9.5/lib/python3.9/site-packages/requests/adapters.py", line 439, in send
    resp = conn.urlopen(
  File "/Users/chinnsenn/.pyenv/versions/3.9.5/lib/python3.9/site-packages/urllib3/connectionpool.py", line 755, in urlopen
    retries = retries.increment(
  File "/Users/chinnsenn/.pyenv/versions/3.9.5/lib/python3.9/site-packages/urllib3/util/retry.py", line 574, in increment
    raise MaxRetryError(_pool, url, error or ResponseError(cause))
urllib3.exceptions.MaxRetryError: SOCKSHTTPSConnectionPool(host='api.ip.sb', port=443): Max retries exceeded with url: /geoip/ (Caused by SSLError(SSLEOFError(8, 'EOF occurred in violation of protocol (_ssl.c:1129)')))

During handling of the above exception, another exception occurred:

Traceback (most recent call last):
  File "/Users/chinnsenn/Developments.localized/PythonProjects/SSRSpeedN-Mod/ssrspeed/utils/geo_ip.py", line 66, in IPLoc
    rep = requests.get("https://api.ip.sb/geoip/{}".format(ip),proxies = {
  File "/Users/chinnsenn/.pyenv/versions/3.9.5/lib/python3.9/site-packages/requests/api.py", line 76, in get
    return request('get', url, params=params, **kwargs)
  File "/Users/chinnsenn/.pyenv/versions/3.9.5/lib/python3.9/site-packages/requests/api.py", line 61, in request
    return session.request(method=method, url=url, **kwargs)
  File "/Users/chinnsenn/.pyenv/versions/3.9.5/lib/python3.9/site-packages/requests/sessions.py", line 542, in request
    resp = self.send(prep, **send_kwargs)
  File "/Users/chinnsenn/.pyenv/versions/3.9.5/lib/python3.9/site-packages/requests/sessions.py", line 655, in send
    r = adapter.send(request, **kwargs)
  File "/Users/chinnsenn/.pyenv/versions/3.9.5/lib/python3.9/site-packages/requests/adapters.py", line 514, in send
    raise SSLError(e, request=request)
requests.exceptions.SSLError: SOCKSHTTPSConnectionPool(host='api.ip.sb', port=443): Max retries exceeded with url: /geoip/ (Caused by SSLError(SSLEOFError(8, 'EOF occurred in violation of protocol (_ssl.c:1129)')))
[2021-10-18 16:32:34,753][INFO][4513287680][speed_test.py:127]Node outbound IP : N/A, Geo : N/A Unknown City, N/A
[2021-10-18 16:32:34,753][INFO][4513287680][speed_test.py:135]Performing netflix test LOCAL_PORT: 1087.
[2021-10-18 16:32:34,788][ERROR][4513287680][speed_test.py:177]代理服务器连接异常：(MaxRetryError("SOCKSHTTPSConnectionPool(host='www.netflix.com', port=443): Max retries exceeded with url: /title/70242311 (Caused by SSLError(SSLEOFError(8, 'EOF occurred in violation of protocol (_ssl.c:1129)')))"),)
[2021-10-18 16:32:34,789][INFO][4513287680][platform_check.py:9]Platform Info : macOS-11.6-x86_64-i386-64bit
[2021-10-18 16:32:34,789][INFO][4513287680][base_client.py:51]Client terminated.
[2021-10-18 16:32:35,793][INFO][4513287680][speed_test.py:242]Starting test 香港 - IPV6 法国 C01 [6/198]
[2021-10-18 16:32:35,794][INFO][4513287680][platform_check.py:9]Platform Info : macOS-11.6-x86_64-i386-64bit
[2021-10-18 16:32:35,795][INFO][4513287680][platform_check.py:9]Platform Info : macOS-11.6-x86_64-i386-64bit
[2021-10-18 16:32:35,795][INFO][4513287680][platform_check.py:9]Platform Info : macOS-11.6-x86_64-i386-64bit
[2021-10-18 16:32:35,795][INFO][4513287680][platform_check.py:9]Platform Info : macOS-11.6-x86_64-i386-64bit
[2021-10-18 16:32:35,801][INFO][4513287680][client_shadowsocks.py:36]Starting Shadowsocks-libev with server 2a05:d012:80f:400:a604:caa0:28d5:d06a:33400
[2021-10-18 16:32:36,807][INFO][4513287680][speed_test.py:276]Client started.
[2021-10-18 16:32:37,826][INFO][4513287680][geo_ip.py:46]Translating 2a05:d012:80f:400:a604:caa0:28d5:d06a to ipv4.
[2021-10-18 16:32:37,826][ERROR][4513287680][geo_ip.py:54]Translate 2a05:d012:80f:400:a604:caa0:28d5:d06a to ipv4 failed.
Traceback (most recent call last):
  File "/Users/chinnsenn/Developments.localized/PythonProjects/SSRSpeedN-Mod/ssrspeed/utils/geo_ip.py", line 51, in domain2ip
    ip = socket.gethostbyname(domain)
socket.gaierror: [Errno 8] nodename nor servname provided, or not known
[2021-10-18 16:32:37,827][ERROR][4513287680][geo_ip.py:61]Invalid IP : N/A
[2021-10-18 16:32:37,827][INFO][4513287680][speed_test.py:111]Node inbound IP : N/A, Geo : N/A Unknown City, N/A
[2021-10-18 16:32:37,828][INFO][4513287680][speed_test_methods.py:72]Testing latency to server.
[2021-10-18 16:32:37,828][ERROR][4513287680][ping.py:36]TCP Ping Exception:
Traceback (most recent call last):
  File "/Users/chinnsenn/Developments.localized/PythonProjects/SSRSpeedN-Mod/ssrspeed/speed_test/test_methods/ping.py", line 24, in tcp_ping
    s.connect((host,port))
socket.gaierror: [Errno 8] nodename nor servname provided, or not known
[2021-10-18 16:32:37,829][ERROR][4513287680][ping.py:36]TCP Ping Exception:
Traceback (most recent call last):
  File "/Users/chinnsenn/Developments.localized/PythonProjects/SSRSpeedN-Mod/ssrspeed/speed_test/test_methods/ping.py", line 24, in tcp_ping
    s.connect((host,port))
socket.gaierror: [Errno 8] nodename nor servname provided, or not known
[2021-10-18 16:32:37,830][ERROR][4513287680][ping.py:36]TCP Ping Exception:
Traceback (most recent call last):
  File "/Users/chinnsenn/Developments.localized/PythonProjects/SSRSpeedN-Mod/ssrspeed/speed_test/test_methods/ping.py", line 24, in tcp_ping
    s.connect((host,port))
socket.gaierror: [Errno 8] nodename nor servname provided, or not known
[2021-10-18 16:32:38,835][INFO][4513287680][geo_ip.py:63]Starting Geo IP.
[2021-10-18 16:32:38,859][ERROR][4513287680][geo_ip.py:76]Geo IP Failed.
Traceback (most recent call last):
  File "/Users/chinnsenn/.pyenv/versions/3.9.5/lib/python3.9/site-packages/urllib3/connectionpool.py", line 699, in urlopen
    httplib_response = self._make_request(
  File "/Users/chinnsenn/.pyenv/versions/3.9.5/lib/python3.9/site-packages/urllib3/connectionpool.py", line 382, in _make_request
    self._validate_conn(conn)
  File "/Users/chinnsenn/.pyenv/versions/3.9.5/lib/python3.9/site-packages/urllib3/connectionpool.py", line 1010, in _validate_conn
    conn.connect()
  File "/Users/chinnsenn/.pyenv/versions/3.9.5/lib/python3.9/site-packages/urllib3/connection.py", line 411, in connect
    self.sock = ssl_wrap_socket(
  File "/Users/chinnsenn/.pyenv/versions/3.9.5/lib/python3.9/site-packages/urllib3/util/ssl_.py", line 449, in ssl_wrap_socket
    ssl_sock = _ssl_wrap_socket_impl(
  File "/Users/chinnsenn/.pyenv/versions/3.9.5/lib/python3.9/site-packages/urllib3/util/ssl_.py", line 493, in _ssl_wrap_socket_impl
    return ssl_context.wrap_socket(sock, server_hostname=server_hostname)
  File "/Users/chinnsenn/.pyenv/versions/3.9.5/lib/python3.9/ssl.py", line 500, in wrap_socket
    return self.sslsocket_class._create(
  File "/Users/chinnsenn/.pyenv/versions/3.9.5/lib/python3.9/ssl.py", line 1040, in _create
    self.do_handshake()
  File "/Users/chinnsenn/.pyenv/versions/3.9.5/lib/python3.9/ssl.py", line 1309, in do_handshake
    self._sslobj.do_handshake()
ssl.SSLEOFError: EOF occurred in violation of protocol (_ssl.c:1129)

During handling of the above exception, another exception occurred:

Traceback (most recent call last):
  File "/Users/chinnsenn/.pyenv/versions/3.9.5/lib/python3.9/site-packages/requests/adapters.py", line 439, in send
    resp = conn.urlopen(
  File "/Users/chinnsenn/.pyenv/versions/3.9.5/lib/python3.9/site-packages/urllib3/connectionpool.py", line 755, in urlopen
    retries = retries.increment(
  File "/Users/chinnsenn/.pyenv/versions/3.9.5/lib/python3.9/site-packages/urllib3/util/retry.py", line 574, in increment
    raise MaxRetryError(_pool, url, error or ResponseError(cause))
urllib3.exceptions.MaxRetryError: SOCKSHTTPSConnectionPool(host='api.ip.sb', port=443): Max retries exceeded with url: /geoip/ (Caused by SSLError(SSLEOFError(8, 'EOF occurred in violation of protocol (_ssl.c:1129)')))

During handling of the above exception, another exception occurred:

Traceback (most recent call last):
  File "/Users/chinnsenn/Developments.localized/PythonProjects/SSRSpeedN-Mod/ssrspeed/utils/geo_ip.py", line 66, in IPLoc
    rep = requests.get("https://api.ip.sb/geoip/{}".format(ip),proxies = {
  File "/Users/chinnsenn/.pyenv/versions/3.9.5/lib/python3.9/site-packages/requests/api.py", line 76, in get
    return request('get', url, params=params, **kwargs)
  File "/Users/chinnsenn/.pyenv/versions/3.9.5/lib/python3.9/site-packages/requests/api.py", line 61, in request
    return session.request(method=method, url=url, **kwargs)
  File "/Users/chinnsenn/.pyenv/versions/3.9.5/lib/python3.9/site-packages/requests/sessions.py", line 542, in request
    resp = self.send(prep, **send_kwargs)
  File "/Users/chinnsenn/.pyenv/versions/3.9.5/lib/python3.9/site-packages/requests/sessions.py", line 655, in send
    r = adapter.send(request, **kwargs)
  File "/Users/chinnsenn/.pyenv/versions/3.9.5/lib/python3.9/site-packages/requests/adapters.py", line 514, in send
    raise SSLError(e, request=request)
requests.exceptions.SSLError: SOCKSHTTPSConnectionPool(host='api.ip.sb', port=443): Max retries exceeded with url: /geoip/ (Caused by SSLError(SSLEOFError(8, 'EOF occurred in violation of protocol (_ssl.c:1129)')))
[2021-10-18 16:32:38,863][INFO][4513287680][speed_test.py:127]Node outbound IP : N/A, Geo : N/A Unknown City, N/A
[2021-10-18 16:32:38,863][INFO][4513287680][speed_test.py:135]Performing netflix test LOCAL_PORT: 1087.
[2021-10-18 16:32:38,880][ERROR][4513287680][speed_test.py:177]代理服务器连接异常：(MaxRetryError("SOCKSHTTPSConnectionPool(host='www.netflix.com', port=443): Max retries exceeded with url: /title/70242311 (Caused by SSLError(SSLEOFError(8, 'EOF occurred in violation of protocol (_ssl.c:1129)')))"),)
[2021-10-18 16:32:38,883][INFO][4513287680][platform_check.py:9]Platform Info : macOS-11.6-x86_64-i386-64bit
[2021-10-18 16:32:38,883][INFO][4513287680][base_client.py:51]Client terminated.
[2021-10-18 16:32:39,886][INFO][4513287680][speed_test.py:242]Starting test 香港 - IPV6 澳大利亚 C01 [7/198]
[2021-10-18 16:32:39,886][INFO][4513287680][platform_check.py:9]Platform Info : macOS-11.6-x86_64-i386-64bit
[2021-10-18 16:32:39,888][INFO][4513287680][platform_check.py:9]Platform Info : macOS-11.6-x86_64-i386-64bit
[2021-10-18 16:32:39,889][INFO][4513287680][platform_check.py:9]Platform Info : macOS-11.6-x86_64-i386-64bit
[2021-10-18 16:32:39,889][INFO][4513287680][platform_check.py:9]Platform Info : macOS-11.6-x86_64-i386-64bit
[2021-10-18 16:32:39,896][INFO][4513287680][client_shadowsocks.py:36]Starting Shadowsocks-libev with server 2406:da1c:1f3:202:348b:dcca:764d:e1fa:33400
[2021-10-18 16:32:40,903][INFO][4513287680][speed_test.py:276]Client started.
[2021-10-18 16:32:41,910][INFO][4513287680][geo_ip.py:46]Translating 2406:da1c:1f3:202:348b:dcca:764d:e1fa to ipv4.
[2021-10-18 16:32:41,910][ERROR][4513287680][geo_ip.py:54]Translate 2406:da1c:1f3:202:348b:dcca:764d:e1fa to ipv4 failed.
Traceback (most recent call last):
  File "/Users/chinnsenn/Developments.localized/PythonProjects/SSRSpeedN-Mod/ssrspeed/utils/geo_ip.py", line 51, in domain2ip
    ip = socket.gethostbyname(domain)
socket.gaierror: [Errno 8] nodename nor servname provided, or not known
[2021-10-18 16:32:41,911][ERROR][4513287680][geo_ip.py:61]Invalid IP : N/A
[2021-10-18 16:32:41,911][INFO][4513287680][speed_test.py:111]Node inbound IP : N/A, Geo : N/A Unknown City, N/A
[2021-10-18 16:32:41,911][INFO][4513287680][speed_test_methods.py:72]Testing latency to server.
[2021-10-18 16:32:41,911][ERROR][4513287680][ping.py:36]TCP Ping Exception:
Traceback (most recent call last):
  File "/Users/chinnsenn/Developments.localized/PythonProjects/SSRSpeedN-Mod/ssrspeed/speed_test/test_methods/ping.py", line 24, in tcp_ping
    s.connect((host,port))
socket.gaierror: [Errno 8] nodename nor servname provided, or not known
[2021-10-18 16:32:41,912][ERROR][4513287680][ping.py:36]TCP Ping Exception:
Traceback (most recent call last):
  File "/Users/chinnsenn/Developments.localized/PythonProjects/SSRSpeedN-Mod/ssrspeed/speed_test/test_methods/ping.py", line 24, in tcp_ping
    s.connect((host,port))
socket.gaierror: [Errno 8] nodename nor servname provided, or not known
[2021-10-18 16:32:41,912][ERROR][4513287680][ping.py:36]TCP Ping Exception:
Traceback (most recent call last):
  File "/Users/chinnsenn/Developments.localized/PythonProjects/SSRSpeedN-Mod/ssrspeed/speed_test/test_methods/ping.py", line 24, in tcp_ping
    s.connect((host,port))
socket.gaierror: [Errno 8] nodename nor servname provided, or not known
[2021-10-18 16:32:42,917][INFO][4513287680][geo_ip.py:63]Starting Geo IP.
[2021-10-18 16:32:42,941][ERROR][4513287680][geo_ip.py:76]Geo IP Failed.
Traceback (most recent call last):
  File "/Users/chinnsenn/.pyenv/versions/3.9.5/lib/python3.9/site-packages/urllib3/connectionpool.py", line 699, in urlopen
    httplib_response = self._make_request(
  File "/Users/chinnsenn/.pyenv/versions/3.9.5/lib/python3.9/site-packages/urllib3/connectionpool.py", line 382, in _make_request
    self._validate_conn(conn)
  File "/Users/chinnsenn/.pyenv/versions/3.9.5/lib/python3.9/site-packages/urllib3/connectionpool.py", line 1010, in _validate_conn
    conn.connect()
  File "/Users/chinnsenn/.pyenv/versions/3.9.5/lib/python3.9/site-packages/urllib3/connection.py", line 411, in connect
    self.sock = ssl_wrap_socket(
  File "/Users/chinnsenn/.pyenv/versions/3.9.5/lib/python3.9/site-packages/urllib3/util/ssl_.py", line 449, in ssl_wrap_socket
    ssl_sock = _ssl_wrap_socket_impl(
  File "/Users/chinnsenn/.pyenv/versions/3.9.5/lib/python3.9/site-packages/urllib3/util/ssl_.py", line 493, in _ssl_wrap_socket_impl
    return ssl_context.wrap_socket(sock, server_hostname=server_hostname)
  File "/Users/chinnsenn/.pyenv/versions/3.9.5/lib/python3.9/ssl.py", line 500, in wrap_socket
    return self.sslsocket_class._create(
  File "/Users/chinnsenn/.pyenv/versions/3.9.5/lib/python3.9/ssl.py", line 1040, in _create
    self.do_handshake()
  File "/Users/chinnsenn/.pyenv/versions/3.9.5/lib/python3.9/ssl.py", line 1309, in do_handshake
    self._sslobj.do_handshake()
ssl.SSLEOFError: EOF occurred in violation of protocol (_ssl.c:1129)

During handling of the above exception, another exception occurred:

Traceback (most recent call last):
  File "/Users/chinnsenn/.pyenv/versions/3.9.5/lib/python3.9/site-packages/requests/adapters.py", line 439, in send
    resp = conn.urlopen(
  File "/Users/chinnsenn/.pyenv/versions/3.9.5/lib/python3.9/site-packages/urllib3/connectionpool.py", line 755, in urlopen
    retries = retries.increment(
  File "/Users/chinnsenn/.pyenv/versions/3.9.5/lib/python3.9/site-packages/urllib3/util/retry.py", line 574, in increment
    raise MaxRetryError(_pool, url, error or ResponseError(cause))
urllib3.exceptions.MaxRetryError: SOCKSHTTPSConnectionPool(host='api.ip.sb', port=443): Max retries exceeded with url: /geoip/ (Caused by SSLError(SSLEOFError(8, 'EOF occurred in violation of protocol (_ssl.c:1129)')))

During handling of the above exception, another exception occurred:

Traceback (most recent call last):
  File "/Users/chinnsenn/Developments.localized/PythonProjects/SSRSpeedN-Mod/ssrspeed/utils/geo_ip.py", line 66, in IPLoc
    rep = requests.get("https://api.ip.sb/geoip/{}".format(ip),proxies = {
  File "/Users/chinnsenn/.pyenv/versions/3.9.5/lib/python3.9/site-packages/requests/api.py", line 76, in get
    return request('get', url, params=params, **kwargs)
  File "/Users/chinnsenn/.pyenv/versions/3.9.5/lib/python3.9/site-packages/requests/api.py", line 61, in request
    return session.request(method=method, url=url, **kwargs)
  File "/Users/chinnsenn/.pyenv/versions/3.9.5/lib/python3.9/site-packages/requests/sessions.py", line 542, in request
    resp = self.send(prep, **send_kwargs)
  File "/Users/chinnsenn/.pyenv/versions/3.9.5/lib/python3.9/site-packages/requests/sessions.py", line 655, in send
    r = adapter.send(request, **kwargs)
  File "/Users/chinnsenn/.pyenv/versions/3.9.5/lib/python3.9/site-packages/requests/adapters.py", line 514, in send
    raise SSLError(e, request=request)
requests.exceptions.SSLError: SOCKSHTTPSConnectionPool(host='api.ip.sb', port=443): Max retries exceeded with url: /geoip/ (Caused by SSLError(SSLEOFError(8, 'EOF occurred in violation of protocol (_ssl.c:1129)')))
[2021-10-18 16:32:42,946][INFO][4513287680][speed_test.py:127]Node outbound IP : N/A, Geo : N/A Unknown City, N/A
[2021-10-18 16:32:42,947][INFO][4513287680][speed_test.py:135]Performing netflix test LOCAL_PORT: 1087.
[2021-10-18 16:32:42,968][ERROR][4513287680][speed_test.py:177]代理服务器连接异常：(MaxRetryError("SOCKSHTTPSConnectionPool(host='www.netflix.com', port=443): Max retries exceeded with url: /title/70242311 (Caused by SSLError(SSLEOFError(8, 'EOF occurred in violation of protocol (_ssl.c:1129)')))"),)
[2021-10-18 16:32:42,973][INFO][4513287680][platform_check.py:9]Platform Info : macOS-11.6-x86_64-i386-64bit
[2021-10-18 16:32:42,974][INFO][4513287680][base_client.py:51]Client terminated.
[2021-10-18 16:32:43,978][INFO][4513287680][speed_test.py:242]Starting test 香港 - 中国-加拿大 IPLC C01 [8/198]
[2021-10-18 16:32:43,979][INFO][4513287680][platform_check.py:9]Platform Info : macOS-11.6-x86_64-i386-64bit
[2021-10-18 16:32:43,979][INFO][4513287680][platform_check.py:9]Platform Info : macOS-11.6-x86_64-i386-64bit
[2021-10-18 16:32:43,980][INFO][4513287680][platform_check.py:9]Platform Info : macOS-11.6-x86_64-i386-64bit
[2021-10-18 16:32:43,980][INFO][4513287680][platform_check.py:9]Platform Info : macOS-11.6-x86_64-i386-64bit
[2021-10-18 16:32:43,984][INFO][4513287680][client_shadowsocks.py:36]Starting Shadowsocks-libev with server ca01.cathayroute.com:33400
[2021-10-18 16:32:44,988][INFO][4513287680][speed_test.py:276]Client started.
[2021-10-18 16:32:45,993][INFO][4513287680][geo_ip.py:46]Translating ca01.cathayroute.com to ipv4.
[2021-10-18 16:32:45,994][INFO][4513287680][geo_ip.py:63]Starting Geo IP.
[2021-10-18 16:32:47,695][INFO][4513287680][speed_test.py:111]Node inbound IP : 117.176.247.22, Geo : China Chengdu, China Mobile Guangdong
[2021-10-18 16:32:47,696][INFO][4513287680][speed_test_methods.py:72]Testing latency to server.
[2021-10-18 16:32:52,302][INFO][4513287680][speed_test_methods.py:68]Testing latency to google.
[2021-10-18 16:32:59,564][INFO][4513287680][geo_ip.py:63]Starting Geo IP.
[2021-10-18 16:33:01,402][INFO][4513287680][speed_test.py:127]Node outbound IP : 35.183.25.99, Geo : Canada Montreal, Amazon.com
[2021-10-18 16:33:01,403][INFO][4513287680][speed_test.py:135]Performing netflix test LOCAL_PORT: 1087.
[2021-10-18 16:33:05,233][INFO][4513287680][speed_test.py:153]Netflix IP : 35.183.25.99
[2021-10-18 16:33:07,158][INFO][4513287680][speed_test.py:167]Netflix test result: 仅自制剧.
[2021-10-18 16:33:07,159][INFO][4513287680][speed_test.py:218]Performing UDP NAT Type Test
[2021-10-18 16:33:08,401][INFO][4513287680][speed_test_methods.py:44]Starting speed test with FAST
[2021-10-18 16:33:08,401][WARNING][4513287680][speed_test.py:374]Re-testing node.
[2021-10-18 16:33:08,402][INFO][4513287680][speed_test_methods.py:44]Starting speed test with FAST
[2021-10-18 16:33:08,402][INFO][4513287680][speed_test.py:386][香港] - [中国-加拿大 IPLC C01] - Loss: [0.00%] - TCP Ping: [360.00] - Google Loss: [0.00%] - Google Ping: [725.00] - AvgStSpeed: [0.00MB/s] - AvgMtSpeed: [0.00MB/s] - NAT Type: Full-cone NAT - Internal End: 10.10.20.57:54320 - Public End: 35.183.25.99:57920
[2021-10-18 16:33:08,403][INFO][4513287680][platform_check.py:9]Platform Info : macOS-11.6-x86_64-i386-64bit
[2021-10-18 16:33:08,403][INFO][4513287680][base_client.py:51]Client terminated.
[2021-10-18 16:33:09,408][INFO][4513287680][speed_test.py:242]Starting test 香港 - 中国-加拿大 IPLC C02 [9/198]
[2021-10-18 16:33:09,409][INFO][4513287680][platform_check.py:9]Platform Info : macOS-11.6-x86_64-i386-64bit
[2021-10-18 16:33:09,410][INFO][4513287680][platform_check.py:9]Platform Info : macOS-11.6-x86_64-i386-64bit
[2021-10-18 16:33:09,410][INFO][4513287680][platform_check.py:9]Platform Info : macOS-11.6-x86_64-i386-64bit
[2021-10-18 16:33:09,410][INFO][4513287680][platform_check.py:9]Platform Info : macOS-11.6-x86_64-i386-64bit
[2021-10-18 16:33:09,416][INFO][4513287680][client_shadowsocks.py:36]Starting Shadowsocks-libev with server ca02.cathayroute.com:33400
[2021-10-18 16:33:10,422][INFO][4513287680][speed_test.py:276]Client started.
[2021-10-18 16:33:11,426][INFO][4513287680][geo_ip.py:46]Translating ca02.cathayroute.com to ipv4.
[2021-10-18 16:33:11,427][INFO][4513287680][geo_ip.py:63]Starting Geo IP.
[2021-10-18 16:33:13,383][INFO][4513287680][speed_test.py:111]Node inbound IP : 117.176.247.22, Geo : China Chengdu, China Mobile Guangdong
[2021-10-18 16:33:13,384][INFO][4513287680][speed_test_methods.py:72]Testing latency to server.
[2021-10-18 16:33:17,810][INFO][4513287680][speed_test_methods.py:68]Testing latency to google.
[2021-10-18 16:33:25,024][INFO][4513287680][geo_ip.py:63]Starting Geo IP.
[2021-10-18 16:33:26,966][INFO][4513287680][speed_test.py:127]Node outbound IP : 35.183.25.99, Geo : Canada Montreal, Amazon.com
[2021-10-18 16:33:26,966][INFO][4513287680][speed_test.py:135]Performing netflix test LOCAL_PORT: 1087.
[2021-10-18 16:33:30,918][INFO][4513287680][speed_test.py:153]Netflix IP : 35.183.25.99
[2021-10-18 16:33:32,820][INFO][4513287680][speed_test.py:167]Netflix test result: 仅自制剧.
[2021-10-18 16:33:32,820][INFO][4513287680][speed_test.py:218]Performing UDP NAT Type Test
[2021-10-18 16:33:33,861][INFO][4513287680][speed_test_methods.py:44]Starting speed test with FAST
[2021-10-18 16:33:33,868][WARNING][4513287680][speed_test.py:374]Re-testing node.
[2021-10-18 16:33:33,868][INFO][4513287680][speed_test_methods.py:44]Starting speed test with FAST
[2021-10-18 16:33:33,868][INFO][4513287680][speed_test.py:386][香港] - [中国-加拿大 IPLC C02] - Loss: [0.00%] - TCP Ping: [342.00] - Google Loss: [0.00%] - Google Ping: [721.00] - AvgStSpeed: [0.00MB/s] - AvgMtSpeed: [0.00MB/s] - NAT Type: Full-cone NAT - Internal End: 10.10.20.57:54320 - Public End: 35.183.25.99:45415
[2021-10-18 16:33:33,869][INFO][4513287680][platform_check.py:9]Platform Info : macOS-11.6-x86_64-i386-64bit
[2021-10-18 16:33:33,869][INFO][4513287680][base_client.py:51]Client terminated.
[2021-10-18 16:33:34,873][INFO][4513287680][speed_test.py:242]Starting test 香港 - 中国-加拿大 IPLC C03 [10/198]
[2021-10-18 16:33:34,873][INFO][4513287680][platform_check.py:9]Platform Info : macOS-11.6-x86_64-i386-64bit
[2021-10-18 16:33:34,874][INFO][4513287680][platform_check.py:9]Platform Info : macOS-11.6-x86_64-i386-64bit
[2021-10-18 16:33:34,874][INFO][4513287680][platform_check.py:9]Platform Info : macOS-11.6-x86_64-i386-64bit
[2021-10-18 16:33:34,874][INFO][4513287680][platform_check.py:9]Platform Info : macOS-11.6-x86_64-i386-64bit
[2021-10-18 16:33:34,880][INFO][4513287680][client_shadowsocks.py:36]Starting Shadowsocks-libev with server ca03.cathayroute.com:33400
[2021-10-18 16:33:35,887][INFO][4513287680][speed_test.py:276]Client started.
[2021-10-18 16:33:36,895][INFO][4513287680][geo_ip.py:46]Translating ca03.cathayroute.com to ipv4.
[2021-10-18 16:33:36,897][INFO][4513287680][geo_ip.py:63]Starting Geo IP.
[2021-10-18 16:33:38,590][INFO][4513287680][speed_test.py:111]Node inbound IP : 117.176.247.22, Geo : China Chengdu, China Mobile Guangdong
[2021-10-18 16:33:38,590][INFO][4513287680][speed_test_methods.py:72]Testing latency to server.
[2021-10-18 16:33:43,214][INFO][4513287680][speed_test_methods.py:68]Testing latency to google.
[2021-10-18 16:33:50,657][INFO][4513287680][geo_ip.py:63]Starting Geo IP.
[2021-10-18 16:33:52,400][INFO][4513287680][speed_test.py:127]Node outbound IP : 35.183.25.99, Geo : Canada Montreal, Amazon.com
[2021-10-18 16:33:52,401][INFO][4513287680][speed_test.py:135]Performing netflix test LOCAL_PORT: 1087.
[2021-10-18 16:33:56,658][INFO][4513287680][speed_test.py:153]Netflix IP : 35.183.25.99
[2021-10-18 16:33:58,657][INFO][4513287680][speed_test.py:167]Netflix test result: 仅自制剧.
[2021-10-18 16:33:58,658][INFO][4513287680][speed_test.py:218]Performing UDP NAT Type Test
[2021-10-18 16:34:01,911][INFO][4513287680][speed_test_methods.py:44]Starting speed test with FAST
[2021-10-18 16:34:01,911][WARNING][4513287680][speed_test.py:374]Re-testing node.
[2021-10-18 16:34:01,911][INFO][4513287680][speed_test_methods.py:44]Starting speed test with FAST
[2021-10-18 16:34:01,911][INFO][4513287680][speed_test.py:386][香港] - [中国-加拿大 IPLC C03] - Loss: [0.00%] - TCP Ping: [361.00] - Google Loss: [0.00%] - Google Ping: [743.00] - AvgStSpeed: [0.00MB/s] - AvgMtSpeed: [0.00MB/s] - NAT Type: Full-cone NAT - Internal End: 10.10.20.57:54320 - Public End: 35.183.25.99:15201
[2021-10-18 16:34:01,912][INFO][4513287680][platform_check.py:9]Platform Info : macOS-11.6-x86_64-i386-64bit
[2021-10-18 16:34:01,912][INFO][4513287680][base_client.py:51]Client terminated.
[2021-10-18 16:34:02,916][INFO][4513287680][speed_test.py:242]Starting test 香港 - 中国-加拿大 IPLC C04 [11/198]
[2021-10-18 16:34:02,917][INFO][4513287680][platform_check.py:9]Platform Info : macOS-11.6-x86_64-i386-64bit
[2021-10-18 16:34:02,918][INFO][4513287680][platform_check.py:9]Platform Info : macOS-11.6-x86_64-i386-64bit
[2021-10-18 16:34:02,918][INFO][4513287680][platform_check.py:9]Platform Info : macOS-11.6-x86_64-i386-64bit
[2021-10-18 16:34:02,919][INFO][4513287680][platform_check.py:9]Platform Info : macOS-11.6-x86_64-i386-64bit
[2021-10-18 16:34:02,926][INFO][4513287680][client_shadowsocks.py:36]Starting Shadowsocks-libev with server ca04.cathayroute.com:33400
[2021-10-18 16:34:03,934][INFO][4513287680][speed_test.py:276]Client started.
[2021-10-18 16:34:04,940][INFO][4513287680][geo_ip.py:46]Translating ca04.cathayroute.com to ipv4.
[2021-10-18 16:34:04,943][INFO][4513287680][geo_ip.py:63]Starting Geo IP.
[2021-10-18 16:34:06,687][INFO][4513287680][speed_test.py:111]Node inbound IP : 117.176.247.22, Geo : China Chengdu, China Mobile Guangdong
[2021-10-18 16:34:06,689][INFO][4513287680][speed_test_methods.py:72]Testing latency to server.
[2021-10-18 16:34:11,639][INFO][4513287680][speed_test_methods.py:68]Testing latency to google.
[2021-10-18 16:34:19,145][INFO][4513287680][geo_ip.py:63]Starting Geo IP.
[2021-10-18 16:34:21,093][INFO][4513287680][speed_test.py:127]Node outbound IP : 35.183.25.99, Geo : Canada Montreal, Amazon.com
[2021-10-18 16:34:21,093][INFO][4513287680][speed_test.py:135]Performing netflix test LOCAL_PORT: 1087.
[2021-10-18 16:34:24,950][INFO][4513287680][speed_test.py:153]Netflix IP : 35.183.25.99
[2021-10-18 16:34:27,024][INFO][4513287680][speed_test.py:167]Netflix test result: 仅自制剧.
[2021-10-18 16:34:27,024][INFO][4513287680][speed_test.py:218]Performing UDP NAT Type Test
[2021-10-18 16:34:28,470][ERROR][4513287680][speed_test.py:227]
Traceback (most recent call last):
  File "/Users/chinnsenn/Developments.localized/PythonProjects/SSRSpeedN-Mod/ssrspeed/speed_test/speed_test.py", line 219, in __nat_type_test
    t, eip, eport, sip = pynat.get_ip_info(
  File "/Users/chinnsenn/.pyenv/versions/3.9.5/lib/python3.9/site-packages/pynat.py", line 238, in get_ip_info
    source_ip = get_internal_ip(stun_addr)
  File "/Users/chinnsenn/.pyenv/versions/3.9.5/lib/python3.9/site-packages/pynat.py", line 163, in get_internal_ip
    sock.connect(test_addr)
socket.gaierror: [Errno 8] nodename nor servname provided, or not known
[2021-10-18 16:34:28,473][INFO][4513287680][speed_test_methods.py:44]Starting speed test with FAST
[2021-10-18 16:34:28,474][WARNING][4513287680][speed_test.py:374]Re-testing node.
[2021-10-18 16:34:28,474][INFO][4513287680][speed_test_methods.py:44]Starting speed test with FAST
[2021-10-18 16:34:28,474][INFO][4513287680][speed_test.py:386][香港] - [中国-加拿大 IPLC C04] - Loss: [0.00%] - TCP Ping: [394.00] - Google Loss: [0.00%] - Google Ping: [750.00] - AvgStSpeed: [0.00MB/s] - AvgMtSpeed: [0.00MB/s]
[2021-10-18 16:34:28,474][INFO][4513287680][platform_check.py:9]Platform Info : macOS-11.6-x86_64-i386-64bit
[2021-10-18 16:34:28,475][INFO][4513287680][base_client.py:51]Client terminated.
[2021-10-18 16:34:29,480][INFO][4513287680][speed_test.py:242]Starting test 香港 - 中国-加拿大 IPLC C05 [12/198]
[2021-10-18 16:34:29,480][INFO][4513287680][platform_check.py:9]Platform Info : macOS-11.6-x86_64-i386-64bit
[2021-10-18 16:34:29,481][INFO][4513287680][platform_check.py:9]Platform Info : macOS-11.6-x86_64-i386-64bit
[2021-10-18 16:34:29,481][INFO][4513287680][platform_check.py:9]Platform Info : macOS-11.6-x86_64-i386-64bit
[2021-10-18 16:34:29,481][INFO][4513287680][platform_check.py:9]Platform Info : macOS-11.6-x86_64-i386-64bit
[2021-10-18 16:34:29,486][INFO][4513287680][client_shadowsocks.py:36]Starting Shadowsocks-libev with server ca05.cathayroute.com:33400
[2021-10-18 16:34:30,491][INFO][4513287680][speed_test.py:276]Client started.
[2021-10-18 16:34:31,500][INFO][4513287680][geo_ip.py:46]Translating ca05.cathayroute.com to ipv4.
[2021-10-18 16:34:31,502][INFO][4513287680][geo_ip.py:63]Starting Geo IP.
[2021-10-18 16:34:32,226][ERROR][4513287680][geo_ip.py:76]Geo IP Failed.
Traceback (most recent call last):
  File "/Users/chinnsenn/Developments.localized/PythonProjects/SSRSpeedN-Mod/ssrspeed/utils/geo_ip.py", line 66, in IPLoc
    rep = requests.get("https://api.ip.sb/geoip/{}".format(ip),proxies = {
  File "/Users/chinnsenn/.pyenv/versions/3.9.5/lib/python3.9/site-packages/requests/api.py", line 76, in get
    return request('get', url, params=params, **kwargs)
  File "/Users/chinnsenn/.pyenv/versions/3.9.5/lib/python3.9/site-packages/requests/api.py", line 61, in request
    return session.request(method=method, url=url, **kwargs)
  File "/Users/chinnsenn/.pyenv/versions/3.9.5/lib/python3.9/site-packages/requests/sessions.py", line 542, in request
    resp = self.send(prep, **send_kwargs)
  File "/Users/chinnsenn/.pyenv/versions/3.9.5/lib/python3.9/site-packages/requests/sessions.py", line 655, in send
    r = adapter.send(request, **kwargs)
  File "/Users/chinnsenn/.pyenv/versions/3.9.5/lib/python3.9/site-packages/requests/adapters.py", line 439, in send
    resp = conn.urlopen(
  File "/Users/chinnsenn/.pyenv/versions/3.9.5/lib/python3.9/site-packages/urllib3/connectionpool.py", line 699, in urlopen
    httplib_response = self._make_request(
  File "/Users/chinnsenn/.pyenv/versions/3.9.5/lib/python3.9/site-packages/urllib3/connectionpool.py", line 382, in _make_request
    self._validate_conn(conn)
  File "/Users/chinnsenn/.pyenv/versions/3.9.5/lib/python3.9/site-packages/urllib3/connectionpool.py", line 1010, in _validate_conn
    conn.connect()
  File "/Users/chinnsenn/.pyenv/versions/3.9.5/lib/python3.9/site-packages/urllib3/connection.py", line 411, in connect
    self.sock = ssl_wrap_socket(
  File "/Users/chinnsenn/.pyenv/versions/3.9.5/lib/python3.9/site-packages/urllib3/util/ssl_.py", line 449, in ssl_wrap_socket
    ssl_sock = _ssl_wrap_socket_impl(
  File "/Users/chinnsenn/.pyenv/versions/3.9.5/lib/python3.9/site-packages/urllib3/util/ssl_.py", line 493, in _ssl_wrap_socket_impl
    return ssl_context.wrap_socket(sock, server_hostname=server_hostname)
  File "/Users/chinnsenn/.pyenv/versions/3.9.5/lib/python3.9/ssl.py", line 500, in wrap_socket
    return self.sslsocket_class._create(
  File "/Users/chinnsenn/.pyenv/versions/3.9.5/lib/python3.9/ssl.py", line 1040, in _create
    self.do_handshake()
  File "/Users/chinnsenn/.pyenv/versions/3.9.5/lib/python3.9/ssl.py", line 1309, in do_handshake
    self._sslobj.do_handshake()
KeyboardInterrupt
[2021-10-18 16:34:32,231][INFO][4513287680][speed_test.py:111]Node inbound IP : 117.176.247.22, Geo : N/A Unknown City, N/A
[2021-10-18 16:34:32,232][INFO][4513287680][speed_test_methods.py:72]Testing latency to server.
[2021-10-18 16:34:32,589][INFO][4513287680][platform_check.py:9]Platform Info : macOS-11.6-x86_64-i386-64bit
[2021-10-18 16:34:32,590][INFO][4513287680][base_client.py:51]Client terminated.
